Workbook
Name \a: #REF!
Name \i: #REF!
Name \j: #REF!
Name \M: #REF!
Name \n: #N/A
Name \R: #REF!
Name \S: #REF!
Name \t: #REF!
Name \w: #REF!
Name \x: #REF!
Name \Z: #REF!
Name ___INDEX_SHEET___ASAP_Utilities: #REF!
Name __adj1: #REF!
Name __CPT1: #REF!
Name __sa01: #REF!
Name __sa07: #REF!
Name __sku08: #REF!
Name __sku09: #REF!
Name _1_date_prochain_jalon: #REF!
Name _1_fonction: #REF!
Name _1_Monnaie: #REF!
Name _1_Montant_charge: #REF!
Name _1_Montant_immo: #REF!
Name _1_Prochain_jalon: #REF!
Name _1_Produit: #REF!
Name _1_Projet: #REF!
Name _1_societe: #REF!
Name _1_Statut: #REF!
Name _1_titre: #REF!
Name _1_uot: #REF!
Name _1_x0: #REF!
Name _1_X1: #REF!
Name _1_x2: #REF!
Name _1_x3: #REF!
Name _2_Monnaie: #REF!
Name _2_Projet: #REF!
Name _21PAGES: #REF!
Name _2BASE_DONNEES: #REF!
Name _3_Date_jalon: #REF!
Name _3_Jalon: #REF!
Name _3_Monnaie: #REF!
Name _3_Montant_Charge: #REF!
Name _3_Montant_Immo: #REF!
Name _3_projet: #REF!
Name _3_Societe: #REF!
Name _3_sous_projet_1: #REF!
Name _3_sous_projet_2: #REF!
Name _4_0_0BASE_DONNEES: #REF!
Name _4_Projet: #REF!
Name _4_Sous_Projet_1: #REF!
Name _4_Sous_Projet_2: #REF!
Name _4BASE_DONNEES: #REF!
Name _6_0_0BASE_DONNEES: #REF!
Name _aaa1: #REF!
Name _adj1: #REF!
Name _API505: #REF!
Name _API506: #REF!
Name _avg2006: #REF!
Name _CPT1: #REF!
Name _DAT1: #REF!

Sheet Cover (1)
A1: Metric Consulting Engineers & Architects Co.,Ltd. | B1: Metric Consulting Engineers & Architects Co.,Ltd. | G1: Document Number: TP-PM-DSN-006 | H1: Document Type: TEMPLATE | I1: Discipline: PMO
G2: Revision: 01 | H2: Issue Date: 07-MAY-26 | I2: Author: PKP
B9: Drawing List
B47: REVISIONS
B49: Rev. | C49: Issued date | D49: Created by | E49: Reviewed by | F49: Approved by | G49: Remark
B50: 00 | C50: 45917 | D50: PKP | E50: ANC | F50: ANC | G50: First issue
B51: 01 | C51: 46149 | D51: PKP | E51: ANC | F51: ANC | G51: Add Create/Review/Approve's Position

Sheet Cover(2)
A1: PROJECT NAME LOCATION, PROVINCE, THAILAND | K1: Insert project name, project location, and client's company logo
B4: Drawing List
B17: DRAWING LIST
B21: Overall Drawing Progress (as of DD Mmm YY) | K21: To input progress for each deliverable submission (optional)
C23: Civil Works | E23: 1
C24: Architectural Works | E24: 1
C25: Structural Works | E25: 1
C26: Mechanical Works | E26: 1
C27: Electrical Works | E27: 1
K39: To register revision of drawing list for each submission.
B40: No. | C40: Description | F40: By | H40: Date | I40: Remarks
A42: DOCUMENT NUMBER | F42: CREATED | H42: REVIEWED | I42: APPROVED
B43: 2XXX-PM-LST-02-Rx Drawing List | F43: Name S. | H43: Name S. | I43: Name S. | K43: Document project number. XXXX indicates Metric's project number. If a project number is 2023-21, XXXX is to be 2321.
F44: PCO | H44: PM | I44: PD

Sheet 1. CIVIL
A1: ='Cover(2)'!A1 -> PROJECT NAME LOCATION, PROVINCE, THAILAND
A3: {=MID(CELL("filename", A1), FIND("]", CELL("filename", A1)) + 1, LEN(CELL("filename", A1)))} -> 1. CIVIL | L3: Responsible
B4: Drawing List | L4: Leader | M4: Execute | N4: Draftman | P4: DD weight | Q4: 50DD | S4: 100DD | U4: Total Progress
A5: Drawing number | D5: Descriptions | F5: Rv. | I5: Size | J5: type | K5: Remark | Q5: Plan | R5: Actual | S5: Plan | T5: Actual
F6: dd MMM | G6: dd MMM | H6: dd MMM
A7: General Drawing
A9: 18043-LM000 01105 | B9: - | C9: DDD | E9: Plot Plan & Location Map | F9: A | L9: AFC | M9: AFC | N9: KSB | P9: 1 | Q9: 0.8 | R9: 0.8 | S9: 1 | T9: 0.95 | U9: =MAX(R9,T9) -> 0.95
A10: 18043-LM000 01105-P | B10: - | C10: DDD | E10: Plot Plan & Location Map | F10: A | L10: AFC | M10: AFC | N10: KSB | P10: 1.5 | Q10: 0.6 | R10: 0.6 | S10: 1 | T10: 0.9 | U10: =MAX(R10,T10) -> 0.9
A11: 18043-LM000 01112 | B11: - | C11: DDD | E11: Covered Passage Way (190-642) - Plans, Section and Detail | F11: A | L11: AFC | M11: AFC | N11: KSB | P11: 1.5 | Q11: 0.6 | R11: 0.6 | S11: 1 | T11: 0.9 | U11: =MAX(R11,T11) -> 0.9
A12: 18043-LM000 01113 | B12: - | C12: DDD | E12: Covered Passage Way (190-642) - Elevations, Sections and Details | F12: A | L12: AFC | M12: AFC | N12: KSB | P12: 1.5 | Q12: 0.6 | R12: 0.2 | S12: 1 | T12: 0.9 | U12: =MAX(R12,T12) -> 0.9
A15: 18043-LMBME 01051 | B15: - | C15: DDD | E15: Project Design Outline | L15: AFC | M15: NPM | N15: KSB | P15: 2.5 | Q15: 0.8 | R15: 0.6 | S15: 1 | T15: 0.9 | U15: =MAX(R15,T15) -> 0.9
A16: 18043-LMBME 01052 | B16: - | C16: DDD | E16: Abbreviation & Finihsing Material list | F16: A | L16: AFC | M16: NPM | N16: KSB | P16: 2.5 | Q16: 0.8 | R16: 0.7 | S16: 1 | T16: 0.9 | U16: =MAX(R16,T16) -> 0.9
A17: 18043-LMBME 01053 | B17: - | C17: DDD | E17: BLDG. 646 & 191-1 Room Schedule | F17: A | L17: AFC | M17: NPM | N17: KSB | P17: 2.5 | Q17: 0.8 | R17: 0.7 | S17: 1 | T17: 0.8 | U17: =MAX(R17,T17) -> 0.8
A18: 18043-LMBME 01054 | B18: - | C18: DDD | E18: ="BLDG. 642 & 190 & 651 - "&MID(#REF!,FIND(" ",#REF!,22)+1,100) -> #REF! | F18: A
A19: 18043-LMBME 01055 | B19: - | C19: DDD | E19: ="BLDG. 642 & 190 & 651 - "&MID(#REF!,FIND(" ",#REF!,22)+1,100) -> #REF! | F19: A
A20: 18043-LMBME 01056 | B20: - | C20: DDD | E20: ="BLDG. 642 & 190 & 651 - "&MID(#REF!,FIND(" ",#REF!,22)+1,100) -> #REF! | F20: A | L20: AFC | M20: NPM | N20: KSB | P20: 2.5 | Q20: 0.6 | R20: 0.6 | S20: 1 | T20: 0.9 | U20: =MAX(R20,T20) -> 0.9
A21: 18043-LMBME 01057 | B21: - | C21: DDD | E21: BLDG. 646 & 191-1 & 191 - Fire Compartment & Evacuation Plan | F21: A | L21: AFC | M21: NPM | N21: KSB | P21: 2.5 | Q21: 0.3 | R21: 0.6 | S21: 1 | T21: 0.9 | U21: =MAX(R21,T21) -> 0.9
L22: AFC | M22: NPM | N22: KSB | P22: 2.5 | Q22: 0.3 | R22: 0.1 | S22: 1 | T22: 0.7 | U22: =MAX(R22,T22) -> 0.7
A24: 18043-LMBMS 01101 | B24: - | C24: DDD | E24: Typical Architectural Details Sheet 1 (Metal roof sheet) | F24: A
A25: 18043-LMBMS 01102 | B25: - | C25: DDD | E25: Typical Architectural Details Sheet 2 (Sandwich panel ) | F25: A | L25: AFC | M25: NPM | N25: KSB | P25: 1.5 | Q25: 0.6 | R25: 0.6 | S25: 1 | T25: 0.9 | U25: =MAX(R25,T25) -> 0.9
A26: 18043-LMBMS 01103 | B26: - | C26: DDD | E26: Typical Architectural Details Sheet 3 (Protection , Handrail) | F26: A | L26: AFC | M26: NPM | N26: KSB | P26: 0.5 | Q26: 0 | R26: 0 | S26: 1 | T26: 0.3 | U26: =MAX(R26,T26) -> 0.3
A27: 18043-LMBMS 01104 | B27: - | C27: DDD | E27: Typical Architectural Details Sheet 4 (Masonry Detail) | F27: A | L27: AFC | M27: NPM | N27: KSB | P27: 0.5 | Q27: 0 | R27: 0 | S27: 1 | T27: 0.3 | U27: =MAX(R27,T27) -> 0.3
A28: 18043-LMBMS 01104 | B28: - | C28: DDD | E28: Typical Architectural Details Sheet 4 (Fire proof joint) | F28: A | L28: AFC | M28: NPM | N28: KSB | P28: 0.5 | Q28: 0 | R28: 0 | S28: 1 | T28: 0.3 | U28: =MAX(R28,T28) -> 0.3
L29: AFC | M29: PTF | N29: PMO | P29: 1.5 | Q29: 0.3 | R29: 0.7 | S29: 1 | T29: 0.8 | U29: =MAX(R29,T29) -> 0.8
L30: AFC | M30: PTF | N30: PMO | P30: 1 | Q30: 0.3 | R30: 0.3 | S30: 1 | T30: 0.8 | U30: =MAX(R30,T30) -> 0.8
E31: ="SUB-TOTAL "&UPPER(A7)&" DRAWINGS" -> SUB-TOTAL GENERAL DRAWING DRAWINGS | I31: =COUNTA(F9:F28) -> 15 | L31: AFC | M31: PTF | N31: PMO | P31: 1 | Q31: 0 | R31: 0 | S31: 1 | T31: 0.8 | U31: =MAX(R31,T31) -> 0.8
L32: AFC | M32: PTF | N32: PMO | P32: 1 | Q32: 0 | R32: 0 | S32: 1 | T32: 0.5 | U32: =MAX(R32,T32) -> 0.5
A33: Building Name or Area Name 1 | L33: AFC | M33: AFC | N33: KSB | P33: 1 | Q33: 0 | R33: 0.4 | S33: 1 | T33: 0.5 | U33: =MAX(R33,T33) -> 0.5
A35: 18043-LM646 01101 | B35: - | C35: DDD | E35: Ground Floor Plan EL.+00 , Mezzanine 1A Floor Plan EL.+10.00 | F35: A
A36: 18043-LM646 01102 | B36: - | C36: DDD | E36: Mezzanine 1B Floor Plan EL.+14.00 & 2nd Floor plan EL.+20.00 | F36: A | L36: AFC | M36: NPM | N36: KSB | P36: 1 | Q36: 0.6 | R36: 0.6 | S36: 1 | T36: 0.9 | U36: =MAX(R36,T36) -> 0.9
A37: 18043-LM646 01103 | B37: - | C37: DDD | E37: Mezzanine 2A Floor Plan EL.+25.00 & 3rd Floor Plan EL.+30.00 | F37: A | L37: AFC | M37: NPM | N37: KSB | P37: 1.5 | Q37: 0.6 | R37: 0.6 | S37: 1 | T37: 0.8 | U37: =MAX(R37,T37) -> 0.8
A38: 18043-LM646 01104 | B38: - | C38: DDD | E38: Roof Plan El.+36.00 | F38: A
A39: 18043-LM646 01105 | B39: - | C39: DDD | E39: Fire Compartment & Evacuation Plan | F39: A
A40: 18043-LM646 01106 | B40: - | C40: DDD | E40: Ground Floor Building Protection Plan | F40: A | L40: AFC | M40: NPM | N40: KSB | P40: 1 | Q40: 0.6 | R40: 0.4 | S40: 1 | T40: 0.5 | U40: =MAX(R40,T40) -> 0.5
A41: 18043-LM646 01107 | B41: - | C41: DDD | E41: Ground Floor Process Clear Height Plan | F41: A | L41: AFC | M41: NPM | N41: KSB | P41: 1.5 | Q41: 0.6 | R41: 0 | S41: 1 | T41: 0.9 | U41: =MAX(R41,T41) -> 0.9
A42: 18043-LM646 01108 | B42: - | C42: DDD | E42: Sections Sheet 1 | F42: A | L42: AFC | M42: NPM | N42: KSB | P42: 1 | Q42: 0 | R42: 0 | S42: 1 | T42: 0.3 | U42: =MAX(R42,T42) -> 0.3
A43: 18043-LM646 01109 | B43: - | C43: DDD | E43: Sections Sheet 2 | F43: A
A44: 18043-LM646 01110 | B44: - | C44: DDD | E44: Sections Sheet 3 | F44: A
A45: 18043-LM646 01111 | B45: - | C45: DDD | E45: Elevations Sheet 1 | F45: A | L45: AFC | M45: AFC | N45: KSB | P45: 1 | Q45: 0.6 | R45: 0.6 | S45: 1 | T45: 0.95 | U45: =MAX(R45,T45) -> 0.95
A46: 18043-LM646 01112 | B46: - | C46: DDD | E46: Elevations Sheet 2 | F46: A | L46: AFC | M46: AFC | N46: KSB | P46: 1 | Q46: 0.6 | R46: 0.6 | S46: 1 | T46: 0.95 | U46: =MAX(R46,T46) -> 0.95
...

Sheet 2. ARCHITECTURAL
A1: ='Cover(2)'!A1 -> PROJECT NAME LOCATION, PROVINCE, THAILAND
A3: {=MID(CELL("filename", A1), FIND("]", CELL("filename", A1)) + 1, LEN(CELL("filename", A1)))} -> 2. ARCHITECTURAL | L3: Responsible
B4: Drawing List | L4: Leader | M4: Execute | N4: Draftman | P4: DD weight | Q4: 50DD | S4: 100DD | U4: Total Progress
A5: Drawing number | D5: Descriptions | F5: Rv. | I5: Size | J5: type | K5: Remark | Q5: Plan | R5: Actual | S5: Plan | T5: Actual
F6: dd MMM | G6: dd MMM | H6: dd MMM
A7: ='1. CIVIL'!A7 -> General Drawing
A9: 18043-LM000 01105 | B9: - | C9: DDD | E9: Plot Plan & Location Map | F9: A | L9: AFC | M9: AFC | N9: KSB | P9: 1 | Q9: 0.8 | R9: 0.8 | S9: 1 | T9: 0.95 | U9: =MAX(R9,T9) -> 0.95
A10: 18043-LM000 01105-P | B10: - | C10: DDD | E10: Plot Plan & Location Map | F10: A | L10: AFC | M10: AFC | N10: KSB | P10: 1.5 | Q10: 0.6 | R10: 0.6 | S10: 1 | T10: 0.9 | U10: =MAX(R10,T10) -> 0.9
A11: 18043-LM000 01112 | B11: - | C11: DDD | E11: Covered Passage Way (190-642) - Plans, Section and Detail | F11: A | L11: AFC | M11: AFC | N11: KSB | P11: 1.5 | Q11: 0.6 | R11: 0.6 | S11: 1 | T11: 0.9 | U11: =MAX(R11,T11) -> 0.9
A12: 18043-LM000 01113 | B12: - | C12: DDD | E12: Covered Passage Way (190-642) - Elevations, Sections and Details | F12: A | L12: AFC | M12: AFC | N12: KSB | P12: 1.5 | Q12: 0.6 | R12: 0.2 | S12: 1 | T12: 0.9 | U12: =MAX(R12,T12) -> 0.9
A15: 18043-LMBME 01051 | B15: - | C15: DDD | E15: Project Design Outline | L15: AFC | M15: NPM | N15: KSB | P15: 2.5 | Q15: 0.8 | R15: 0.6 | S15: 1 | T15: 0.9 | U15: =MAX(R15,T15) -> 0.9
A16: 18043-LMBME 01052 | B16: - | C16: DDD | E16: Abbreviation & Finihsing Material list | F16: A | L16: AFC | M16: NPM | N16: KSB | P16: 2.5 | Q16: 0.8 | R16: 0.7 | S16: 1 | T16: 0.9 | U16: =MAX(R16,T16) -> 0.9
A17: 18043-LMBME 01053 | B17: - | C17: DDD | E17: BLDG. 646 & 191-1 Room Schedule | F17: A | L17: AFC | M17: NPM | N17: KSB | P17: 2.5 | Q17: 0.8 | R17: 0.7 | S17: 1 | T17: 0.8 | U17: =MAX(R17,T17) -> 0.8
A18: 18043-LMBME 01054 | B18: - | C18: DDD | E18: ="BLDG. 642 & 190 & 651 - "&MID(#REF!,FIND(" ",#REF!,22)+1,100) -> #REF! | F18: A
A19: 18043-LMBME 01055 | B19: - | C19: DDD | E19: ="BLDG. 642 & 190 & 651 - "&MID(#REF!,FIND(" ",#REF!,22)+1,100) -> #REF! | F19: A
A20: 18043-LMBME 01056 | B20: - | C20: DDD | E20: ="BLDG. 642 & 190 & 651 - "&MID(#REF!,FIND(" ",#REF!,22)+1,100) -> #REF! | F20: A | L20: AFC | M20: NPM | N20: KSB | P20: 2.5 | Q20: 0.6 | R20: 0.6 | S20: 1 | T20: 0.9 | U20: =MAX(R20,T20) -> 0.9
A21: 18043-LMBME 01057 | B21: - | C21: DDD | E21: BLDG. 646 & 191-1 & 191 - Fire Compartment & Evacuation Plan | F21: A | L21: AFC | M21: NPM | N21: KSB | P21: 2.5 | Q21: 0.3 | R21: 0.6 | S21: 1 | T21: 0.9 | U21: =MAX(R21,T21) -> 0.9
L22: AFC | M22: NPM | N22: KSB | P22: 2.5 | Q22: 0.3 | R22: 0.1 | S22: 1 | T22: 0.7 | U22: =MAX(R22,T22) -> 0.7
A24: 18043-LMBMS 01101 | B24: - | C24: DDD | E24: Typical Architectural Details Sheet 1 (Metal roof sheet) | F24: A
A25: 18043-LMBMS 01102 | B25: - | C25: DDD | E25: Typical Architectural Details Sheet 2 (Sandwich panel ) | F25: A | L25: AFC | M25: NPM | N25: KSB | P25: 1.5 | Q25: 0.6 | R25: 0.6 | S25: 1 | T25: 0.9 | U25: =MAX(R25,T25) -> 0.9
A26: 18043-LMBMS 01103 | B26: - | C26: DDD | E26: Typical Architectural Details Sheet 3 (Protection , Handrail) | F26: A | L26: AFC | M26: NPM | N26: KSB | P26: 0.5 | Q26: 0 | R26: 0 | S26: 1 | T26: 0.3 | U26: =MAX(R26,T26) -> 0.3
A27: 18043-LMBMS 01104 | B27: - | C27: DDD | E27: Typical Architectural Details Sheet 4 (Masonry Detail) | F27: A | L27: AFC | M27: NPM | N27: KSB | P27: 0.5 | Q27: 0 | R27: 0 | S27: 1 | T27: 0.3 | U27: =MAX(R27,T27) -> 0.3
A28: 18043-LMBMS 01104 | B28: - | C28: DDD | E28: Typical Architectural Details Sheet 4 (Fire proof joint) | F28: A | L28: AFC | M28: NPM | N28: KSB | P28: 0.5 | Q28: 0 | R28: 0 | S28: 1 | T28: 0.3 | U28: =MAX(R28,T28) -> 0.3
L29: AFC | M29: PTF | N29: PMO | P29: 1.5 | Q29: 0.3 | R29: 0.7 | S29: 1 | T29: 0.8 | U29: =MAX(R29,T29) -> 0.8
L30: AFC | M30: PTF | N30: PMO | P30: 1 | Q30: 0.3 | R30: 0.3 | S30: 1 | T30: 0.8 | U30: =MAX(R30,T30) -> 0.8
E31: ="SUB-TOTAL "&UPPER(A7)&" DRAWINGS" -> SUB-TOTAL GENERAL DRAWING DRAWINGS | I31: =COUNTA(F9:F28) -> 15 | L31: AFC | M31: PTF | N31: PMO | P31: 1 | Q31: 0 | R31: 0 | S31: 1 | T31: 0.8 | U31: =MAX(R31,T31) -> 0.8
L32: AFC | M32: PTF | N32: PMO | P32: 1 | Q32: 0 | R32: 0 | S32: 1 | T32: 0.5 | U32: =MAX(R32,T32) -> 0.5
A33: ='1. CIVIL'!A33 -> Building Name or Area Name 1 | L33: AFC | M33: AFC | N33: KSB | P33: 1 | Q33: 0 | R33: 0.4 | S33: 1 | T33: 0.5 | U33: =MAX(R33,T33) -> 0.5
A35: 18043-LM646 01101 | B35: - | C35: DDD | E35: Ground Floor Plan EL.+00 , Mezzanine 1A Floor Plan EL.+10.00 | F35: A
A36: 18043-LM646 01102 | B36: - | C36: DDD | E36: Mezzanine 1B Floor Plan EL.+14.00 & 2nd Floor plan EL.+20.00 | F36: A | L36: AFC | M36: NPM | N36: KSB | P36: 1 | Q36: 0.6 | R36: 0.6 | S36: 1 | T36: 0.9 | U36: =MAX(R36,T36) -> 0.9
A37: 18043-LM646 01103 | B37: - | C37: DDD | E37: Mezzanine 2A Floor Plan EL.+25.00 & 3rd Floor Plan EL.+30.00 | F37: A | L37: AFC | M37: NPM | N37: KSB | P37: 1.5 | Q37: 0.6 | R37: 0.6 | S37: 1 | T37: 0.8 | U37: =MAX(R37,T37) -> 0.8
A38: 18043-LM646 01104 | B38: - | C38: DDD | E38: Roof Plan El.+36.00 | F38: A
A39: 18043-LM646 01105 | B39: - | C39: DDD | E39: Fire Compartment & Evacuation Plan | F39: A
A40: 18043-LM646 01106 | B40: - | C40: DDD | E40: Ground Floor Building Protection Plan | F40: A | L40: AFC | M40: NPM | N40: KSB | P40: 1 | Q40: 0.6 | R40: 0.4 | S40: 1 | T40: 0.5 | U40: =MAX(R40,T40) -> 0.5
A41: 18043-LM646 01107 | B41: - | C41: DDD | E41: Ground Floor Process Clear Height Plan | F41: A | L41: AFC | M41: NPM | N41: KSB | P41: 1.5 | Q41: 0.6 | R41: 0 | S41: 1 | T41: 0.9 | U41: =MAX(R41,T41) -> 0.9
A42: 18043-LM646 01108 | B42: - | C42: DDD | E42: Sections Sheet 1 | F42: A | L42: AFC | M42: NPM | N42: KSB | P42: 1 | Q42: 0 | R42: 0 | S42: 1 | T42: 0.3 | U42: =MAX(R42,T42) -> 0.3
A43: 18043-LM646 01109 | B43: - | C43: DDD | E43: Sections Sheet 2 | F43: A
A44: 18043-LM646 01110 | B44: - | C44: DDD | E44: Sections Sheet 3 | F44: A
A45: 18043-LM646 01111 | B45: - | C45: DDD | E45: Elevations Sheet 1 | F45: A | L45: AFC | M45: AFC | N45: KSB | P45: 1 | Q45: 0.6 | R45: 0.6 | S45: 1 | T45: 0.95 | U45: =MAX(R45,T45) -> 0.95
A46: 18043-LM646 01112 | B46: - | C46: DDD | E46: Elevations Sheet 2 | F46: A | L46: AFC | M46: AFC | N46: KSB | P46: 1 | Q46: 0.6 | R46: 0.6 | S46: 1 | T46: 0.95 | U46: =MAX(R46,T46) -> 0.95
...

Sheet 3. STRUCTURAL
A1: ='Cover(2)'!A1 -> PROJECT NAME LOCATION, PROVINCE, THAILAND
A3: {=MID(CELL("filename", A1), FIND("]", CELL("filename", A1)) + 1, LEN(CELL("filename", A1)))} -> 3. STRUCTURAL | L3: Responsible
B4: Drawing List | L4: Leader | M4: Execute | N4: Draftman | P4: DD weight | Q4: 50DD | S4: 100DD | U4: Total Progress
A5: Drawing number | D5: Descriptions | F5: Rv. | I5: Size | J5: type | K5: Remark | Q5: Plan | R5: Actual | S5: Plan | T5: Actual
F6: dd MMM | G6: dd MMM | H6: dd MMM
A7: ='1. CIVIL'!A7 -> General Drawing
A8: 18043-LMBMS 01501 | B8: - | C8: DDD | E8: Typical Structural Details & General Notes Sheet 1 | F8: A | L8: AFC | M8: AFC | N8: KSB | P8: 0 | Q8: 0.8 | R8: 0.8 | S8: 1 | T8: 0.95 | U8: =MAX(R8,T8) -> 0.95
A9: 18043-LMBMS 01502 | B9: - | C9: DDD | E9: Typical Structural Details & General Notes Sheet 2 | F9: A | L9: AFC | M9: AFC | N9: KSB | P9: 1 | Q9: 0.8 | R9: 0.8 | S9: 1 | T9: 0.95 | U9: =MAX(R9,T9) -> 0.95
A10: 18043-LMBMS 01503 | B10: - | C10: DDD | E10: Typical Structural Details & General Notes Sheet 3 | F10: A | L10: AFC | M10: AFC | N10: KSB | P10: 1.5 | Q10: 0.6 | R10: 0.6 | S10: 1 | T10: 0.9 | U10: =MAX(R10,T10) -> 0.9
A11: 18043-LMBMS 01701 | B11: - | C11: DDD | E11: Typical Steel Connection Sheet 1 | F11: A | L11: AFC | M11: AFC | N11: KSB | P11: 1.5 | Q11: 0.6 | R11: 0.6 | S11: 1 | T11: 0.9 | U11: =MAX(R11,T11) -> 0.9
A12: 18043-LMBMS 01702 | B12: - | C12: DDD | E12: Typical Steel Connection Sheet 2 | F12: A | L12: AFC | M12: AFC | N12: KSB | P12: 1.5 | Q12: 0.6 | R12: 0.2 | S12: 1 | T12: 0.9 | U12: =MAX(R12,T12) -> 0.9
A13: 18043-LMBMS 01703 | B13: - | C13: DDD | E13: Typical Steel Connection Sheet 3 | F13: A | L13: AFC | M13: AFC | N13: KSB | P13: 2.5 | Q13: 0.6 | R13: 0.2 | S13: 1 | T13: 0.9 | U13: =MAX(R13,T13) -> 0.9
A15: 18043-LMBME 01501 | B15: - | C15: DDD | E15: Overall Demolition Floor Plan | F15: A | L15: AFC | M15: NPM | N15: KSB | P15: 2.5 | Q15: 0.8 | R15: 0.6 | S15: 1 | T15: 0.9 | U15: =MAX(R15,T15) -> 0.9
A16: 18043-LMBME 01502 | B16: - | C16: DDD | E16: Demolition Floor Plan sheet1 | F16: A | L16: AFC | M16: NPM | N16: KSB | P16: 2.5 | Q16: 0.8 | R16: 0.7 | S16: 1 | T16: 0.9 | U16: =MAX(R16,T16) -> 0.9
A17: 18043-LMBME 01503 | B17: - | C17: DDD | E17: Demolition Floor Plan sheet2 | F17: A | L17: AFC | M17: NPM | N17: KSB | P17: 2.5 | Q17: 0.8 | R17: 0.7 | S17: 1 | T17: 0.8 | U17: =MAX(R17,T17) -> 0.8
E19: ="SUB-TOTAL "&UPPER(A7)&" DRAWINGS" -> SUB-TOTAL GENERAL DRAWING DRAWINGS | I19: =COUNTA(F8:F17) -> 9
A21: ='1. CIVIL'!A33 -> Building Name or Area Name 1
A22: 18043-LM646 01501 | B22: - | C22: DDD | E22: Piling Plan | F22: A | L22: AFC | M22: NPM | N22: KSB | P22: -1.5 | Q22: 0.6 | R22: 0.6 | S22: 1 | T22: 0.9 | U22: =MAX(R22,T22) -> 0.9
A23: 18043-LM646 01502 | B23: - | C23: DDD | E23: Foundation Plan | F23: A | L23: AFC | M23: NPM | N23: KSB | P23: -0.5 | Q23: 0.6 | R23: 0.6 | S23: 1 | T23: 0.9 | U23: =MAX(R23,T23) -> 0.9
A24: 18043-LM646 01503 | B24: - | C24: DDD | E24: 1 Floor Loading Plan | F24: A | L24: AFC | M24: NPM | N24: KSB | P24: 0.5 | Q24: 0.6 | R24: 0.6 | S24: 1 | T24: 0.9 | U24: =MAX(R24,T24) -> 0.9
A25: 18043-LM646 01504 | B25: - | C25: DDD | E25: 1 Floor Framing Plan | F25: A | L25: AFC | M25: NPM | N25: KSB | P25: 1.5 | Q25: 0.6 | R25: 0.6 | S25: 1 | T25: 0.9 | U25: =MAX(R25,T25) -> 0.9
A26: 18043-LM646 01505 | B26: - | C26: DDD | E26: 1.1 Floor Loading Plan | F26: A | L26: AFC | M26: NPM | N26: KSB | P26: 0.5 | Q26: 0 | R26: 0 | S26: 1 | T26: 0.3 | U26: =MAX(R26,T26) -> 0.3
A27: 18043-LM646 01506 | B27: - | C27: DDD | E27: 1.1 Floor Framing Plan | F27: A | L27: AFC | M27: NPM | N27: KSB | P27: 0.5 | Q27: 0 | R27: 0 | S27: 1 | T27: 0.3 | U27: =MAX(R27,T27) -> 0.3
A28: 18043-LM646 01507 | B28: - | C28: DDD | E28: 1.2 Floor Loading Plan | F28: A | L28: AFC | M28: NPM | N28: KSB | P28: 0.5 | Q28: 0 | R28: 0 | S28: 1 | T28: 0.3 | U28: =MAX(R28,T28) -> 0.3
A29: 18043-LM646 01508 | B29: - | C29: DDD | E29: 1.2 Floor Framing Plan | F29: A | L29: AFC | M29: PTF | N29: PMO | P29: 1.5 | Q29: 0.3 | R29: 0.7 | S29: 1 | T29: 0.8 | U29: =MAX(R29,T29) -> 0.8
A30: 18043-LM646 01509 | B30: - | C30: DDD | E30: 2 Floor Loading Plan | F30: A | L30: AFC | M30: PTF | N30: PMO | P30: 1 | Q30: 0.3 | R30: 0.3 | S30: 1 | T30: 0.8 | U30: =MAX(R30,T30) -> 0.8
A31: 18043-LM646 01510 | B31: - | C31: DDD | E31: 2 Floor Framing Plan | F31: A | L31: AFC | M31: PTF | N31: PMO | P31: 1 | Q31: 0 | R31: 0 | S31: 1 | T31: 0.8 | U31: =MAX(R31,T31) -> 0.8
A32: 18043-LM646 01511 | B32: - | C32: DDD | E32: 2.1 Floor Loading Plan | F32: A | L32: AFC | M32: PTF | N32: PMO | P32: 1 | Q32: 0 | R32: 0 | S32: 1 | T32: 0.5 | U32: =MAX(R32,T32) -> 0.5
A33: 18043-LM646 01512 | B33: - | C33: DDD | E33: 2.1 Floor Framing Plan | F33: A | L33: AFC | M33: AFC | N33: KSB | P33: 1 | Q33: 0 | R33: 0.4 | S33: 1 | T33: 0.5 | U33: =MAX(R33,T33) -> 0.5
... A93: 18043-LM646 01782 | B93: - | C93: DDD | E93: Specific Steel Connection Details Sheet2 | F93: A | L93: AFC | M93: AFC | N93: KSB | P93: 36 | Q93: 0.6 | R93: 0.6 | S93: 1 | T93: 0.3 | U93: =MAX(R93,T93) -> 0.6
E95: ="SUB-TOTAL "&UPPER(A21)&" DRAWINGS" -> SUB-TOTAL BUILDING NAME OR AREA NAME 1 DRAWINGS | I95: =COUNTA(F22:I95) -> 60
A97: ='1. CIVIL'!A61 -> Building Name or Area Name 2
A98: 18043-LM191-1 01501 | B98: - | C98: DDD | E98: Piling Plan | F98: A | L98: AFC | M98: AFC | N98: KSB | P98: 41 | Q98: 0.6 | R98: 0.6 | S98: 1 | T98: 0.3 | U98: =MAX(R98,T98) -> 0.6
A99: 18043-LM191-1 01502 | B99: - | C99: DDD | E99: Foundation Plan | F99: A | L99: AFC | M99: AFC | N99: KSB | P99: 42 | Q99: 0.6 | R99: 0.6 | S99: 1 | T99: 0.3 | U99: =MAX(R99,T99) -> 0.6
A100: 18043-LM191-1 01503 | B100: - | C100: DDD | E100: Ground Floor Loading Plan | F100: A | L100: AFC | M100: AFC | N100: KSB | P100: 43 | Q100: 0.6 | R100: 0.6 | S100: 1 | T100: 0.3 | U100: =MAX(R100,T100) -> 0.6
A101: 18043-LM191-1 01504 | B101: - | C101: DDD | E101: Ground Floor Framing Plan | F101: A | L101: AFC | M101: AFC | N101: KSB | P101: 44 | Q101: 0.6 | R101: 0.6 | S101: 1 | T101: 0.3 | U101: =MAX(R101,T101) -> 0.6
A102: 18043-LM191-1 01505 | B102: - | C102: DDD | E102: 2nd Floor Loading Plan | F102: A | L102: AFC | M102: AFC | N102: KSB | P102: 45 | Q102: 0.6 | R102: 0.6 | S102: 1 | T102: 0.3 | U102: =MAX(R102,T102) -> 0.6
A103: 18043-LM191-1 01506 | B103: - | C103: DDD | E103: 2nd Floor Framing Plan | F103: A | L103: AFC | M103: AFC | N103: KSB | P103: 46 | Q103: 0.6 | R103: 0.6 | S103: 1 | T103: 0.3 | U103: =MAX(R103,T103) -> 0.6
A104: 18043-LM191-1 01507 | B104: - | C104: DDD | E104: 3rd Floor Loading Plan | F104: A | L104: AFC | M104: AFC | N104: KSB | P104: 47 | Q104: 0.6 | R104: 0.6 | S104: 1 | T104: 0.3 | U104: =MAX(R104,T104) -> 0.6
A105: 18043-LM191-1 01508 | B105: - | C105: DDD | E105: 3rd Floor Framing Plan | F105: A | L105: AFC | M105: AFC | N105: KSB | P105: 48 | Q105: 0.6 | R105: 0.6 | S105: 1 | T105: 0.3 | U105: =MAX(R105,T105) -> 0.6
...

Sheet 4. MECHANICAL
A1: ='Cover(2)'!A1 -> PROJECT NAME LOCATION, PROVINCE, THAILAND
A3: {=MID(CELL("filename", A1), FIND("]", CELL("filename", A1)) + 1, LEN(CELL("filename", A1)))} -> 4. MECHANICAL | L3: Responsible
B4: Drawing List | L4: Leader | M4: Execute | N4: Draftman | P4: DD weight | Q4: 50DD | S4: 100DD | U4: Total Progress
A5: Drawing number | D5: Descriptions | F5: Rv. | I5: Size | J5: type | K5: Remark | Q5: Plan | R5: Actual | S5: Plan | T5: Actual
F6: dd MMM | G6: dd MMM | H6: dd MMM
A7: ='1. CIVIL'!A7 -> General Drawing
A8: ="18043-"&LEFT(W8,11) -> 18043-LMBMS 08214 | B8: - | C8: DDD | E8: =MID(W8,FIND(" ",W8,15)+2,100) -> Typical Details Sheet 1 | F8: A | I8: A0 | L8: AFC | M8: AFC | N8: KSB | P8: 0 | Q8: 0.8 | R8: 0.8 | S8: 1 | T8: 0.95 | U8: =MAX(R8,T8) -> 0.95 | W8: LMBMS 08214 Rv.7A Typical Details Sheet 1
A9: ="18043-"&LEFT(W9,11) -> 18043-LMBMS 08215 | B9: - | C9: DDD | E9: =MID(W9,FIND(" ",W9,15)+2,100) -> Typical Details Sheet 2 | F9: A | I9: A0 | L9: AFC | M9: AFC | N9: KSB | P9: 1 | Q9: 0.8 | R9: 0.8 | S9: 1 | T9: 0.95 | U9: =MAX(R9,T9) -> 0.95 | W9: LMBMS 08215 Rv.7A Typical Details Sheet 2
A10: ="18043-"&LEFT(W10,11) -> 18043-LMBMS 08217 | B10: - | C10: DDD | E10: =MID(W10,FIND(" ",W10,15)+2,100) -> Fire Door Operation Typical Details | F10: A | I10: A0 | L10: AFC | M10: AFC | N10: KSB | P10: 1.5 | Q10: 0.6 | R10: 0.6 | S10: 1 | T10: 0.9 | U10: =MAX(R10,T10) -> 0.9 | W10: LMBMS 08217 Rv.5 Fire Door Operation Typical Details
A11: ="18043-"&LEFT(W11,11) -> 18043-LMBMS 08218 | B11: - | C11: DDD | E11: =MID(W11,FIND(" ",W11,15)+2,100) -> Fire Protection Abbreviation and General Note | F11: A | I11: A0 | L11: AFC | M11: AFC | N11: KSB | P11: 1.5 | Q11: 0.6 | R11: 0.6 | S11: 1 | T11: 0.9 | U11: =MAX(R11,T11) -> 0.9 | W11: LMBMS 08218 Rv.4A Fire Protection Abbreviation and General Note
A12: ="18043-"&LEFT(W12,11) -> 18043-LMBMS 08219 | B12: - | C12: DDD | E12: =MID(W12,FIND(" ",W12,15)+2,100) -> Typical Details Sheet 3 | F12: A | I12: A0 | L12: AFC | M12: AFC | N12: KSB | P12: 1.5 | Q12: 0.6 | R12: 0.2 | S12: 1 | T12: 0.9 | U12: =MAX(R12,T12) -> 0.9 | W12: LMBMS 08219 Rv.3A Typical Details Sheet 3
A14: ="18043-"&LEFT(W14,11) -> 18043-LMBMS 08311 | B14: - | C14: DDD | E14: =MID(W14,FIND(" ",W14,15)+1,100) -> Typical Details Sheet 1 | F14: A | I14: A0 | L14: AFC | M14: AFC | N14: KSB | P14: 3.5 | Q14: 0.6 | R14: 0.2 | S14: 1 | T14: 0.9 | U14: =MAX(R14,T14) -> 0.9 | W14: LMBMS 08311 Rv.16 Typical Details Sheet 1
A15: ="18043-"&LEFT(W15,11) -> 18043-LMBMS 08312 | B15: - | C15: DDD | E15: =MID(W15,FIND(" ",W15,15)+1,100) -> Typical Details Sheet 2 | F15: A | I15: A0 | L15: AFC | M15: NPM | N15: KSB | P15: 2.5 | Q15: 0.8 | R15: 0.6 | S15: 1 | T15: 0.9 | U15: =MAX(R15,T15) -> 0.9 | W15: LMBMS 08312 Rv.16 Typical Details Sheet 2
A16: ="18043-"&LEFT(W16,11) -> 18043-LMBMS 08313 | B16: - | C16: DDD | E16: =MID(W16,FIND(" ",W16,15)+1,100) -> Typical Details Sheet 3 | F16: A | I16: A0 | L16: AFC | M16: NPM | N16: KSB | P16: 2.5 | Q16: 0.8 | R16: 0.7 | S16: 1 | T16: 0.9 | U16: =MAX(R16,T16) -> 0.9 | W16: LMBMS 08313 Rv.16 Typical Details Sheet 3
A17: ="18043-"&LEFT(W17,11) -> 18043-LMBMS 08314 | B17: - | C17: DDD | E17: =MID(W17,FIND(" ",W17,15)+1,100) -> Typical Details Sheet 4 | F17: A | I17: A0 | L17: AFC | M17: NPM | N17: KSB | P17: 2.5 | Q17: 0.8 | R17: 0.7 | S17: 1 | T17: 0.8 | U17: =MAX(R17,T17) -> 0.8 | W17: LMBMS 08314 Rv.16 Typical Details Sheet 4
A18: ="18043-"&LEFT(W18,11) -> 18043-LMBMS 08315 | B18: - | C18: DDD | E18: =MID(W18,FIND(" ",W18,15)+1,100) -> Typical Details Sheet 5 | F18: A | I18: A0 | L18: AFC | M18: NPM | N18: KSB | P18: 3.5 | Q18: 0.8 | R18: 0.7 | S18: 1 | T18: 0.8 | U18: =MAX(R18,T18) -> 0.8 | W18: LMBMS 08315 Rv.16 Typical Details Sheet 5
A20: ="18043-"&LEFT(W20,11) -> 18043-LMBMS 08513 | B20: - | C20: DDD | E20: =MID(W20,FIND(" ",W20,15)+1,100) -> Typical Details Sheet 1 | F20: A | I20: A0 | L20: AFC | M20: NPM | N20: KSB | P20: 5.5 | Q20: 0.8 | R20: 0.7 | S20: 1 | T20: 0.8 | U20: =MAX(R20,T20) -> 0.8 | W20: LMBMS 08513 Rv.13 Typical Details Sheet 1
A21: ="18043-"&LEFT(W21,11) -> 18043-LMBMS 08514 | B21: - | C21: DDD | E21: =MID(W21,FIND(" ",W21,15)+1,100) -> Typical Details Sheet 2 | F21: A | I21: A0 | L21: AFC | M21: NPM | N21: KSB | P21: 6.5 | Q21: 0.8 | R21: 0.7 | S21: 1 | T21: 0.8 | U21: =MAX(R21,T21) -> 0.8 | W21: LMBMS 08514 Rv.13 Typical Details Sheet 2
A22: ="18043-"&LEFT(W22,11) -> 18043-LMBMS 08515 | B22: - | C22: DDD | E22: =MID(W22,FIND(" ",W22,15)+1,100) -> Typical Details Sheet 3 | F22: A | I22: A0 | L22: AFC | M22: NPM | N22: KSB | P22: -1.5 | Q22: 0.6 | R22: 0.6 | S22: 1 | T22: 0.9 | U22: =MAX(R22,T22) -> 0.9 | W22: LMBMS 08515 Rv.13 Typical Details Sheet 3
A23: ="18043-"&LEFT(W23,11) -> 18043-LMBMS 08517 | B23: - | C23: DDD | E23: =MID(W23,FIND(" ",W23,15)+1,100) -> Fluids Abbreviation and General Note | F23: A | I23: A0 | L23: AFC | M23: NPM | N23: KSB | P23: -0.5 | Q23: 0.6 | R23: 0.6 | S23: 1 | T23: 0.9 | U23: =MAX(R23,T23) -> 0.9 | W23: LMBMS 08517 Rv.2 Fluids Abbreviation and General Note
A25: ="18043-"&LEFT(W25,11) -> 18043-LMBMS 09301 | B25: - | C25: DDD | E25: =MID(W25,FIND(" ",W25,15)+1,100) -> Control Unit and Wiring Typical Details Sheet 1 | F25: A | I25: A3 | L25: AFC | M25: NPM | N25: KSB | P25: 1.5 | Q25: 0.6 | R25: 0.6 | S25: 1 | T25: 0.9 | U25: =MAX(R25,T25) -> 0.9 | W25: LMBMS 09301 Rv.6 Control Unit and Wiring Typical Details Sheet 1
A26: ="18043-"&LEFT(W26,11) -> 18043-LMBMS 09302 | B26: - | C26: DDD | E26: =MID(W26,FIND(" ",W26,15)+1,100) -> Control Unit and Wiring Typical Details Sheet 2 | F26: A | I26: A3 | L26: AFC | M26: NPM | N26: KSB | P26: 0.5 | Q26: 0 | R26: 0 | S26: 1 | T26: 0.3 | U26: =MAX(R26,T26) -> 0.3 | W26: LMBMS 09302 Rv.9 Control Unit and Wiring Typical Details Sheet 2
A28: ="18043-"&LEFT(W28,11) -> 18043-LM000 08251 | B28: - | C28: DDD | E28: =MID(W28,FIND(" ",W28,15)+1,100) -> Outside Building - Fire Protection System - Modification Plan | F28: A | I28: A0 | L28: AFC | M28: NPM | N28: KSB | P28: 0.5 | Q28: 0 | R28: 0 | S28: 1 | T28: 0.3 | U28: =MAX(R28,T28) -> 0.3 | W28: LM000 08251 Rv.10 Outside Building - Fire Protection System - Modification Plan | AD28: LMBME 08222 Rv.1C Overall Layout - Piping Outside Building Plan
A30: ="18043-"&LEFT(W30,11) -> 18043-LMBME 08553 | B30: - | C30: DDD | E30: =MID(W30,FIND(" ",W30,15)+1,100) -> Main Pipe Racks Fluid Distribution Diagram | F30: A | I30: A0 | L30: AFC | M30: PTF | N30: PMO | P30: 1 | Q30: 0.3 | R30: 0.3 | S30: 1 | T30: 0.8 | U30: =MAX(R30,T30) -> 0.8 | W30: LMBME 08553 Rv.18 Main Pipe Racks Fluid Distribution Diagram
E34: ="SUB-TOTAL "&UPPER(A7)&" DRAWINGS" -> SUB-TOTAL GENERAL DRAWING DRAWINGS | I34: =COUNTA(F8:F33) -> 18
A36: ='1. CIVIL'!A33 -> Building Name or Area Name 1
A37: ="18043-"&LEFT(W37,11) -> 18043-LM000 08253 | B37: - | C37: DDD | E37: =MID(W37,FIND(" ",W37,15)+1,100) -> Covered Passageway (190-642) - Fire Protection Plan & Sections | F37: A | I37: A0 | L37: AFC | M37: NPM | N37: KSB | P37: 1.5 | Q37: 0.6 | R37: 0.6 | S37: 1 | T37: 0.8 | U37: =MAX(R37,T37) -> 0.8 | W37: LM000 08253 Rv.3 Covered Passageway (190-642) - Fire Protection Plan & Sections
A38: ="18043-"&LEFT(W38,11) -> 18043-LM000 08504 | B38: - | C38: DDD | E38: =MID(W38,FIND(" ",W38,15)+1,100) -> Bladder Post, AFC Workshop & TBM Workshop - Piping Plans & Details | F38: A | I38: A0 | L38: AFC | M38: NPM | N38: KSB | P38: 2.5 | Q38: 0.6 | R38: 0.6 | S38: 1 | T38: 0.8 | U38: =MAX(R38,T38) -> 0.8 | W38: LM000 08504 Rv.3 Bladder Post, AFC Workshop & TBM Workshop - Piping Plans & Details
A39: ="18043-"&LEFT(W39,11) -> 18043-LMBME 08560 | B39: - | C39: DDD | E39: =MID(W39,FIND(" ",W39,15)+1,100) -> Main Pipes Rack Piping Layout | F39: A | I39: A0 | L39: AFC | M39: NPM | N39: KSB | P39: 3.5 | Q39: 0.6 | R39: 0.6 | S39: 1 | T39: 0.8 | U39: =MAX(R39,T39) -> 0.8 | W39: LMBME 08560 Rv.0c Main Pipes Rack Piping Layout
A41: ="18043-"&LEFT(W41,11) -> 18043-LM103 08201 | B41: - | C41: DDD | E41: =MID(W41,FIND(" ",W41,15)+1,100) -> Fire Water System - Plans | F41: A | I41: A0 | L41: AFC | M41: NPM | N41: KSB | P41: 1.5 | Q41: 0.6 | R41: 0 | S41: 1 | T41: 0.9 | U41: =MAX(R41,T41) -> 0.9 | W41: LM103 08201 Rv.5 Fire Water System - Plans
A42: ="18043-"&LEFT(W42,11) -> 18043-LM103 08202 | B42: - | C42: DDD | E42: =MID(W42,FIND(" ",W42,15)+1,100) -> Fire Water System - Sections | F42: A | I42: A0 | L42: AFC | M42: NPM | N42: KSB | P42: 1 | Q42: 0 | R42: 0 | S42: 1 | T42: 0.3 | U42: =MAX(R42,T42) -> 0.3 | W42: LM103 08202 Rv.2 Fire Water System - Sections
A43: ="18043-"&LEFT(W43,11) -> 18043-LM103 08203 | B43: - | C43: DDD | E43: =MID(W43,FIND(" ",W43,15)+1,100) -> LV2 Room - PLans & Diagram | F43: A | I43: A0 | L43: AFC | M43: NPM | N43: KSB | P43: 2 | Q43: 0 | R43: 0 | S43: 1 | T43: 0.3 | U43: =MAX(R43,T43) -> 0.3 | W43: LM103 08203 Rv.A LV2 Room - PLans & Diagram
A44: ="18043-"&LEFT(W44,11) -> 18043-LM103 08301 | B44: - | C44: DDD | E44: =MID(W44,FIND(" ",W44,15)+1,100) -> Air Conditioning & Ventilation System - P&I Diagram | F44: A | I44: A0 | L44: AFC | M44: NPM | N44: KSB | P44: 3 | Q44: 0 | R44: 0 | S44: 1 | T44: 0.3 | U44: =MAX(R44,T44) -> 0.3 | W44: LM103 08301 Rv.3 Air Conditioning & Ventilation System - P&I Diagram
A45: ="18043-"&LEFT(W45,11) -> 18043-LM103 08302 | B45: - | C45: DDD | E45: =MID(W45,FIND(" ",W45,15)+1,100) -> Air Conditioning & Ventilation System - Plan & Section | F45: A | I45: A0 | L45: AFC | M45: AFC | N45: KSB | P45: 1 | Q45: 0.6 | R45: 0.6 | S45: 1 | T45: 0.95 | U45: =MAX(R45,T45) -> 0.95 | W45: LM103 08302 Rv.3 Air Conditioning & Ventilation System - Plan & Section
A47: ="18043-"&LEFT(W47,11) -> 18043-LM263 08101 | B47: - | C47: DDD | E47: =MID(W47,FIND(" ",W47,15)+1,100) -> Plumbing Plan and Details | F47: A | I47: A0 | L47: AFC | M47: AFC | N47: KSB | P47: 1 | Q47: 0.3 | R47: 0.3 | S47: 1 | T47: 0.95 | U47: =MAX(R47,T47) -> 0.95 | W47: LM263 08101 Rv.0 Plumbing Plan and Details
A48: ="18043-"&LEFT(W48,11) -> 18043-LM263 08301 | B48: - | C48: DDD | E48: =MID(W48,FIND(" ",W48,15)+1,100) -> Ventilation Plans | F48: A | I48: A0 | L48: AFC | M48: AFC | N48: KSB | P48: 2 | Q48: 0.3 | R48: 0.3 | S48: 1 | T48: 0.95 | U48: =MAX(R48,T48) -> 0.95 | W48: LM263 08301 Rv.0 Ventilation Plans
A50: ="18043-"&LEFT(W50,11) -> 18043-LM642 08251 | B50: - | C50: DDD | E50: =MID(W50,FIND(" ",W50,15)+1,100) -> Fire Protection Plan & Section | F50: A | I50: A0 | L50: AFC | M50: AFC | N50: KSB | P50: 1 | Q50: 0.6 | R50: 0.6 | S50: 1 | T50: 0.95 | U50: =MAX(R50,T50) -> 0.95 | W50: LM642 08251 Rv.8 Fire Protection Plan & Section
A51: ="18043-"&LEFT(W51,11) -> 18043-LM642 08302 | B51: - | C51: DDD | E51: HVAC System - Plans & Sections | F51: A | I51: A0 | L51: AFC | M51: AFC | N51: KSB | P51: 1 | Q51: 0.3 | R51: 0.6 | S51: 1 | T51: 0.95 | U51: =MAX(R51,T51) -> 0.95 | W51: LM642 08302
A53: ="18043-"&LEFT(W53,11) -> 18043-LM651 08201 | B53: - | C53: DDD | E53: =MID(W53,FIND(" ",W53,15)+1,100) -> Fire Water System - Plan & Sections | F53: A | I53: A0 | L53: AFC | M53: AFC | N53: KSB | P53: 3 | Q53: 0.3 | R53: 0.6 | S53: 1 | T53: 0.95 | U53: =MAX(R53,T53) -> 0.95 | W53: LM651 08201 Rv.2 Fire Water System - Plan & Sections
A54: ="18043-"&LEFT(W54,11) -> 18043-LM651 08301 | B54: - | C54: DDD | E54: =MID(W54,FIND(" ",W54,15)+1,100) -> Air Conditioning System - Plan, Section And P&I Diagram | F54: A | I54: A0 | L54: AFC | M54: AFC | N54: KSB | P54: 1 | Q54: 0.3 | R54: 0 | S54: 1 | T54: 0.3 | U54: =MAX(R54,T54) -> 0.3 | W54: LM651 08301 Rv.2 Air Conditioning System - Plan, Section And P&I Diagram
...

Sheet 5. ELECTRICAL
A1: ='Cover(2)'!A1 -> PROJECT NAME LOCATION, PROVINCE, THAILAND
A3: {=MID(CELL("filename", A1), FIND("]", CELL("filename", A1)) + 1, LEN(CELL("filename", A1)))} -> 5. ELECTRICAL | L3: Responsible
B4: Drawing List | L4: Leader | M4: Execute | N4: Draftman | P4: DD weight | Q4: 50DD | S4: 100DD | U4: Total Progress
A5: Drawing number | D5: Descriptions | F5: Rv. | I5: Size | J5: type | K5: Remark | Q5: Plan | R5: Actual | S5: Plan | T5: Actual
F6: dd MMM | G6: dd MMM | H6: dd MMM
A7: General Drawing
A9: ="18043-"&LEFT(W9,11) -> 18043-LMBMS 09017 | B9: - | C9: DDD | E9: =MID(W9,FIND(" ",W9,15)+1,100) -> Electrical Legend and Symbols | F9: A | L9: AFC | M9: AFC | N9: KSB | P9: 1 | Q9: 0.8 | R9: 0.8 | S9: 1 | T9: 0.95 | U9: =MAX(R9,T9) -> 0.95 | W9: LMBMS 09017 Rv.16B Electrical Legend and Symbols
A10: ="18043-"&LEFT(W10,11) -> 18043-LMBMS 09026 | B10: - | C10: DDD | E10: =MID(W10,FIND(" ",W10,15)+1,100) -> Electrical Typical Details Sheet 1 | F10: A | L10: AFC | M10: AFC | N10: KSB | P10: 1.5 | Q10: 0.6 | R10: 0.6 | S10: 1 | T10: 0.9 | U10: =MAX(R10,T10) -> 0.9 | W10: LMBMS 09026 Rv.A Electrical Typical Details Sheet 1
A11: ="18043-"&LEFT(W11,11) -> 18043-LMBMS 09027 | B11: - | C11: DDD | E11: =MID(W11,FIND(" ",W11,15)+1,100) -> Electrical Typical Details Sheet 2 | F11: A | L11: AFC | M11: AFC | N11: KSB | P11: 1.5 | Q11: 0.6 | R11: 0.6 | S11: 1 | T11: 0.9 | U11: =MAX(R11,T11) -> 0.9 | W11: LMBMS 09027 Rv.A Electrical Typical Details Sheet 2
A12: ="18043-"&LEFT(W12,11) -> 18043-LMBMS 09028 | B12: - | C12: DDD | E12: =MID(W12,FIND(" ",W12,15)+1,100) -> Electrical Typical Details Sheet 3 | F12: A | L12: AFC | M12: AFC | N12: KSB | P12: 1.5 | Q12: 0.6 | R12: 0.2 | S12: 1 | T12: 0.9 | U12: =MAX(R12,T12) -> 0.9 | W12: LMBMS 09028 Rv.A Electrical Typical Details Sheet 3
A13: ="18043-"&LEFT(W13,11) -> 18043-LMBMS 09029 | B13: - | C13: DDD | E13: =MID(W13,FIND(" ",W13,15)+1,100) -> Electrical Typical Details Sheet 4 | F13: A | L13: AFC | M13: AFC | N13: KSB | P13: 2.5 | Q13: 0.6 | R13: 0.2 | S13: 1 | T13: 0.9 | U13: =MAX(R13,T13) -> 0.9 | W13: LMBMS 09029 Rv.A Electrical Typical Details Sheet 4
A14: ="18043-"&LEFT(W14,11) -> 18043-LMBMS 09030 | B14: - | C14: DDD | E14: =MID(W14,FIND(" ",W14,15)+1,100) -> Electrical Typical Details Sheet 5 | F14: A | L14: AFC | M14: AFC | N14: KSB | P14: 3.5 | Q14: 0.6 | R14: 0.2 | S14: 1 | T14: 0.9 | U14: =MAX(R14,T14) -> 0.9 | W14: LMBMS 09030 Rv.A Electrical Typical Details Sheet 5
A15: ="18043-"&LEFT(W15,11) -> 18043-LMBMS 09031 | B15: - | C15: DDD | E15: =MID(W15,FIND(" ",W15,15)+1,100) -> Lighting Specification | F15: A | L15: AFC | M15: NPM | N15: KSB | P15: 2.5 | Q15: 0.8 | R15: 0.6 | S15: 1 | T15: 0.9 | U15: =MAX(R15,T15) -> 0.9 | W15: LMBMS 09031 Rv.A Lighting Specification
A17: ="18043-"&LEFT(W17,11) -> 18043-LM000 09558 | B17: - | C17: DDD | E17: =MID(W17,FIND(" ",W17,15)+1,100) -> General Electrical Work - Cable Tray Layout For B.191 (Modification) | F17: A | L17: AFC | M17: NPM | N17: KSB | P17: 2.5 | Q17: 0.8 | R17: 0.7 | S17: 1 | T17: 0.8 | U17: =MAX(R17,T17) -> 0.8 | W17: LM000 09558 Rv.1 General Electrical Work - Cable Tray Layout For B.191 (Modification)
A18: ="18043-"&LEFT(W18,11) -> 18043-LM000 09577 | B18: - | C18: DDD | E18: =MID(W18,FIND(" ",W18,15)+1,100) -> Main feeder layout plan 646 Building | F18: A | L18: AFC | M18: NPM | N18: KSB | P18: 3.5 | Q18: 0.8 | R18: 0.7 | S18: 1 | T18: 0.8 | U18: =MAX(R18,T18) -> 0.8 | W18: LM000 09577 Rv.A Main feeder layout plan 646 Building
A19: ="18043-"&LEFT(W19,11) -> 18043-LM000 09578 | B19: - | C19: DDD | E19: =MID(W19,FIND(" ",W19,15)+1,100) -> Main feeder layout plan 191-1 Building | F19: A | L19: AFC | M19: NPM | N19: KSB | P19: 4.5 | Q19: 0.8 | R19: 0.7 | S19: 1 | T19: 0.8 | U19: =MAX(R19,T19) -> 0.8 | W19: LM000 09578 Rv.A Main feeder layout plan 191-1 Building
A20: ="18043-"&LEFT(W20,11) -> 18043-LM000 09579 | B20: - | C20: DDD | E20: =MID(W20,FIND(" ",W20,15)+1,100) -> Main feeder layout plan 190 D xxx | F20: A | L20: AFC | M20: NPM | N20: KSB | P20: 5.5 | Q20: 0.8 | R20: 0.7 | S20: 1 | T20: 0.8 | U20: =MAX(R20,T20) -> 0.8 | W20: LM000 09579 Rv.A Main feeder layout plan 190 D xxx
E23: ="SUB-TOTAL "&UPPER(A7)&" DRAWINGS" -> SUB-TOTAL GENERAL DRAWING DRAWINGS | I23: =COUNTA(F9:F21) -> 11
A25: ='1. CIVIL'!A33 -> Building Name or Area Name 1
A27: ="18043-"&LEFT(W27,11) -> 18043-LM646 09101 | B27: - | C27: DDD | E27: =MID(W27,FIND(" ",W27,15)+1,100) -> List of Lighting Requirement | F27: A | L27: AFC | M27: NPM | N27: KSB | P27: 1.5 | Q27: 0 | R27: 0 | S27: 1 | T27: 0.3 | U27: =MAX(R27,T27) -> 0.3 | W27: LM646 09101 Rv.A List of Lighting Requirement
A28: ="18043-"&LEFT(W28,11) -> 18043-LM646 09102 | C28: DDD | E28: =MID(W28,FIND(" ",W28,15)+1,100) -> 1st Floor Lighting Plan | F28: A | L28: AFC | M28: NPM | N28: KSB | P28: 0.5 | Q28: 0 | R28: 0 | S28: 1 | T28: 0.3 | U28: =MAX(R28,T28) -> 0.3 | W28: LM646 09102 Rv.A 1st Floor Lighting Plan
A29: ="18043-"&LEFT(W29,11) -> 18043-LM646 09103 | C29: DDD | E29: =MID(W29,FIND(" ",W29,15)+1,100) -> 1st Floor Mezzanine Lighting Plan | F29: A | L29: AFC | M29: NPM | N29: KSB | P29: 1.5 | Q29: 0 | R29: 0 | S29: 1 | T29: 0.3 | U29: =MAX(R29,T29) -> 0.3 | W29: LM646 09103 Rv.A 1st Floor Mezzanine Lighting Plan
A30: ="18043-"&LEFT(W30,11) -> 18043-LM646 09104 | C30: DDD | E30: =MID(W30,FIND(" ",W30,15)+1,100) -> 2nd Floor Lighting Plan | F30: A | L30: AFC | M30: PTF | N30: PMO | P30: 1 | Q30: 0.3 | R30: 0.3 | S30: 1 | T30: 0.8 | U30: =MAX(R30,T30) -> 0.8 | W30: LM646 09104 Rv.A 2nd Floor Lighting Plan
A31: ="18043-"&LEFT(W31,11) -> 18043-LM646 09105 | C31: DDD | E31: =MID(W31,FIND(" ",W31,15)+1,100) -> 2nd Floor Mezzanine Lighting Plan | F31: A | L31: AFC | M31: PTF | N31: PMO | P31: 2 | Q31: 0.3 | R31: 0.3 | S31: 1 | T31: 0.8 | U31: =MAX(R31,T31) -> 0.8 | W31: LM646 09105 Rv.A 2nd Floor Mezzanine Lighting Plan
A32: ="18043-"&LEFT(W32,11) -> 18043-LM646 09106 | C32: DDD | E32: =MID(W32,FIND(" ",W32,15)+1,100) -> 1st Floor Emergency Light and Exit Light Plan | F32: A | L32: AFC | M32: PTF | N32: PMO | P32: 3 | Q32: 0.3 | R32: 0.3 | S32: 1 | T32: 0.8 | U32: =MAX(R32,T32) -> 0.8 | W32: LM646 09106 Rv.A 1st Floor Emergency Light and Exit Light Plan
A33: ="18043-"&LEFT(W33,11) -> 18043-LM646 09107 | C33: DDD | E33: =MID(W33,FIND(" ",W33,15)+1,100) -> 1st Floor Mezzanine Emergency Light and Exit Light Plan | F33: A | L33: AFC | M33: PTF | N33: PMO | P33: 4 | Q33: 0.3 | R33: 0.3 | S33: 1 | T33: 0.8 | U33: =MAX(R33,T33) -> 0.8 | W33: LM646 09107 Rv.A 1st Floor Mezzanine Emergency Light and Exit Light Plan
A34: ="18043-"&LEFT(W34,11) -> 18043-LM646 09108 | C34: DDD | E34: =MID(W34,FIND(" ",W34,15)+1,100) -> 2nd Floor Emergency Light and Exit Light Plan | F34: A | L34: AFC | M34: PTF | N34: PMO | P34: 5 | Q34: 0.3 | R34: 0.3 | S34: 1 | T34: 0.8 | U34: =MAX(R34,T34) -> 0.8 | W34: LM646 09108 Rv.A 2nd Floor Emergency Light and Exit Light Plan
A35: ="18043-"&LEFT(W35,11) -> 18043-LM646 09109 | C35: DDD | E35: =MID(W35,FIND(" ",W35,15)+1,100) -> 2nd Floor Mezzanine Emergency Light and Exit Light Plan | F35: A | L35: AFC | M35: PTF | N35: PMO | P35: 6 | Q35: 0.3 | R35: 0.3 | S35: 1 | T35: 0.8 | U35: =MAX(R35,T35) -> 0.8 | W35: LM646 09109 Rv.A 2nd Floor Mezzanine Emergency Light and Exit Light Plan
A36: ="18043-"&LEFT(W36,11) -> 18043-LM646 09110 | C36: DDD | E36: =MID(W36,FIND(" ",W36,15)+1,100) -> 1st Floor Receptacle and Power Supply Plan | F36: A | L36: AFC | M36: PTF | N36: PMO | P36: 7 | Q36: 0.3 | R36: 0.3 | S36: 1 | T36: 0.8 | U36: =MAX(R36,T36) -> 0.8 | W36: LM646 09110 Rv.A 1st Floor Receptacle and Power Supply Plan
A37: ="18043-"&LEFT(W37,11) -> 18043-LM646 09111 | C37: DDD | E37: =MID(W37,FIND(" ",W37,15)+1,100) -> 1st Floor Mezzanine Receptacle and Power Supply Plan | F37: A | L37: AFC | M37: NPM | N37: KSB | P37: 1.5 | Q37: 0.6 | R37: 0.6 | S37: 1 | T37: 0.8 | U37: =MAX(R37,T37) -> 0.8 | W37: LM646 09111 Rv.A 1st Floor Mezzanine Receptacle and Power Supply Plan
A38: ="18043-"&LEFT(W38,11) -> 18043-LM646 09112 | C38: DDD | E38: =MID(W38,FIND(" ",W38,15)+1,100) -> 2nd Floor Receptacle and Power Supply Plan | F38: A | L38: AFC | M38: NPM | N38: KSB | P38: 2.5 | Q38: 0.6 | R38: 0.6 | S38: 1 | T38: 0.8 | U38: =MAX(R38,T38) -> 0.8 | W38: LM646 09112 Rv.A 2nd Floor Receptacle and Power Supply Plan
A39: ="18043-"&LEFT(W39,11) -> 18043-LM646 09113 | C39: DDD | E39: =MID(W39,FIND(" ",W39,15)+1,100) -> 2nd Floor Mezzanine Receptacle and Power Supply Plan | F39: A | L39: AFC | M39: NPM | N39: KSB | P39: 3.5 | Q39: 0.6 | R39: 0.6 | S39: 1 | T39: 0.8 | U39: =MAX(R39,T39) -> 0.8 | W39: LM646 09113 Rv.A 2nd Floor Mezzanine Receptacle and Power Supply Plan
... A62: ="18043-"&LEFT(W62,11) -> 18043-LM646 09702 | C62: DDD | E62: =MID(W62,FIND(" ",W62,15)+1,100) -> Grounding System Plan | F62: A | L62: AFC | M62: AFC | N62: KSB | P62: 5 | Q62: 0.6 | R62: 0.6 | S62: 1 | T62: 0.3 | U62: =MAX(R62,T62) -> 0.6 | W62: LM646 09702 Rv.A Grounding System Plan
E64: ="SUB-TOTAL "&UPPER(A25)&" DRAWINGS" -> SUB-TOTAL BUILDING NAME OR AREA NAME 1 DRAWINGS | I64: =COUNTA(F27:F62) -> 36
A66: ='1. CIVIL'!A61 -> Building Name or Area Name 2
A68: ="18043-"&LEFT(W68,13) -> 18043-LM191-1 09101 | B68: - | C68: DDD | E68: =MID(W68,FIND(" ",W68,15)+1,100) -> List of Lighting Requirement | F68: A | L68: AFC | M68: AFC | N68: KSB | P68: 11 | Q68: 0.6 | R68: 0.6 | S68: 1 | T68: 0.3 | U68: =MAX(R68,T68) -> 0.6 | W68: LM191-1 09101 Rv.A List of Lighting Requirement
A69: ="18043-"&LEFT(W69,13) -> 18043-LM191-1 09102 | B69: - | C69: DDD | E69: =MID(W69,FIND(" ",W69,15)+1,100) -> Ground and 2nd Floor Lighting, Emergency Light and Exit Light Plans | F69: A | L69: AFC | M69: AFC | N69: KSB | P69: 12 | Q69: 0.6 | R69: 0.6 | S69: 1 | T69: 0.3 | U69: =MAX(R69,T69) -> 0.6 | W69: LM191-1 09102 Rv.A Ground and 2nd Floor Lighting, Emergency Light and Exit Light Plans
A70: ="18043-"&LEFT(W70,13) -> 18043-LM191-1 09103 | B70: - | C70: DDD | E70: =MID(W70,FIND(" ",W70,15)+1,100) -> 3rd and Roof Floor Lighting, Emergency Light and Exit Light Plans | F70: A | L70: AFC | M70: AFC | N70: KSB | P70: 13 | Q70: 0.6 | R70: 0.6 | S70: 1 | T70: 0.3 | U70: =MAX(R70,T70) -> 0.6 | W70: LM191-1 09103 Rv.A 3rd and Roof Floor Lighting, Emergency Light and Exit Light Plans
A71: ="18043-"&LEFT(W71,13) -> 18043-LM191-1 09201 | B71: - | C71: DDD | E71: =MID(W71,FIND(" ",W71,15)+1,100) -> Fire Alarm System Diagram, Ground and 2nd Floor Fire Alarm Plans | F71: A | L71: AFC | M71: AFC | N71: KSB | P71: 14 | Q71: 0.6 | R71: 0.6 | S71: 1 | T71: 0.3 | U71: =MAX(R71,T71) -> 0.6 | W71: LM191-1 09201 Rv.A Fire Alarm System Diagram, Ground and 2nd Floor Fire Alarm Plans
A72: ="18043-"&LEFT(W72,13) -> 18043-LM191-1 09202 | B72: - | C72: DDD | E72: =MID(W72,FIND(" ",W72,15)+1,100) -> 3rd and Roof Floor Fire Alarm Plans | F72: A | L72: AFC | M72: AFC | N72: KSB | P72: 15 | Q72: 0.6 | R72: 0.6 | S72: 1 | T72: 0.3 | U72: =MAX(R72,T72) -> 0.6 | W72: LM191-1 09202 Rv.A 3rd and Roof Floor Fire Alarm Plans
...

Sheet Eng name
B1: ตรวจสอบความถูกต้องแล้ว | C1: prof. id | D1: ชื่อ-สกุล | E1: English Name
A2: Arch
A3: Architect 1 | C3: ว-สถ. 607 | D3: อัญชลี เหล่าบุญเจริญ | E3: UNCHARLEE LAOBOONCHAROEN
A4: Architect 2 | B4: Drawing List | C4: ภ-สถ. 22586 | D4: ภาคภูมิ แก้วมี | E4: PARKPOOM KAEWMEE
A5: Architect 3 | C5: ภ-สถ. 25517 | D5: ปวีณา ธนวุฒิจิราวัชร | E5: PAWEENA THANAWUTCHIRAWAT
A7: Structural
A8: Structural Engineer 1 | C8: สย. 9776 | D8: พิชิต ผาติเวทย์ | E8: PICHIT PHATIWET
A9: Structural Engineer 2 | C9: สย.10758 | D9: ณภัค ศรีบุญเรือง | E9: NAPAK SRIBOONRUENG
A10: Structural Engineer 3 | C10: ภย.53735 | D10: พิมพ์ประภา ขวัญพ่วง | E10: PIMPRAPA KHWANPUANG
A11: Structural Engineer 4 | C11: ภย.74343 | D11: เขมทัต ธนะชัย | E11: KHEMMATAT THANACHAI
A12: Structural Engineer 5 | C12: ภย.89064 | D12: ธนาธิป กลิ่นเฟื่อง | E12: THANATHIP KLINFUEANG
A13: Structural Engineer 6 | D13: จิรวัฒน์ คชบก | E13: CHIRAWAT KOCHABOG
A15: Civil
A16: Civil Engineer 1 | C16: ภย.75757 | D16: อัรฟาน เจะอาลี | E16: ARFARN CHEALI
A19: Mech.
A20: Mechanical Engineer 1 | C20: สก. 3504 | D20: คชฤทธิ์ จ่างพิพัฒน์นวกิจ | E20: KOTCHARIT JANGPIPATNAVAKIT
A21: Mechanical Engineer 2 | C21: ภก. 45707 | D21: กิตติพศ พูนเต็ม | E21: KITTIPOT POONTEM
A22: Mechanical Engineer 3 | C22: ภก. 52671 | D22: ธิติวุฒิ สุวรรณคาม | E22: THITIWUT SUWANNAKAM
A23: Mechanical Engineer 4 | C23: ภก. 54219 | D23: คาวี ศรีเงิน | E23: KAWEE SRINGOEN
A24: Mechanical Engineer 5 | C24: ภก. 57198 | D24: พันธิตร โลหกิจ | E24: PANTHID LOHAKIT
A27: Elec.
A28: Electrical Engineer 1 | C28: วฟก. 993 | D28: ศุภชัย ลิมปนากร | E28: SUPACHAI LIMPANAKORN
A29: Electrical Engineer 2 | C29: ภฟก. 63154 | D29: เกียรติศักดิ์ วงศ์พานิช | E29: KIATTISAK VONGPHANICH
A30: Electrical Engineer 3 | C30: ภฟก. 67684 | D30: กฤติน สิริโภคากร | E30: KRITTIN SIRIPOKAKORN
A31: Electrical Engineer 4 | C31: ภฟก. 67463 | D31: ภูริภัทร์ อัศวภิญโญชัย | E31: PURIPHAT ASAWAPINYOCHAI
A32: Electrical Engineer 5 | C32: ภฟก. 68732 | D32: ณัฐพัชร์ เหล่ากาญจนอุดม | E32: NATTAPAT LAOKRANJANAUDOM
A35: Sanitary
C36: ภส. 1034 | D36: คชฤทธิ์ จ่างพิพัฒน์นวกิจ | E36: KOTCHARIT JANGPIPATNAVAKIT

Sheet Numbering System
B1: Project : LMC PF1 ROR
B2: Owner : Michelin Laemchabang
B3: DRAWING NUMBERING CONTROL (Drawing no.)
B4: Drawing List | D4: Factory | F4: Bldg No. | H4: Discipline / number | J4: Phase
B5: 18043 | C5: - | D5: LM | F5: XXX | H5: XXXXX | I5: - | J5: XXX
B7: DRAWING NUMBERING CONTROL (File name)
B8: Proj Number | D8: Factory | F8: Bldg No. | H8: Discipline / number | J8: Phase | L8: Revision | O8: Drawing name
B9: 18043 | C9: - | D9: LM | F9: XXX | H9: XXXXX | I9: - | J9: XXX | K9: - | L9: A | O9: XXX
B12: Drawing no. | D12: 18043-LM000 01105-DDD
B14: File Name | D14: 180430-LM000 01105-DDD-A Plot plan
B18: Proj. Number | D18: 18043
J19: กรณีแบบที่ทำต่อๆๆๆๆ กันเลขหมด หรืออะไรก็ตาม
B20: Factory | D20: LM | J20: ไม่ต้องรันเลขต่อก็ได้ (แบบที่ปกติเราทำ)
J21: ให้ใช้เลขซ้ำได้เลย
J22: เพราะเรามีเลขโปรเจคอยู่แล้ว ไม่ซ้ำแน่นอน
B23: Area | D23: 646 | F23: ASRS Building
D24: wait MSC | F24: Curing office & Workshop
D25: 520 | F25: Cold Preparation Workshop
D26: 561 | F26: TBM Workshop
D27: 191 | F27: After Curing Workshop
D28: 642 | F28: Modification of Hot Water Improvement
D30: BME | F30: Code used for drawing showing several buildings
D31: BMS | F31: Code used for standard details ( Typical detail)
B32: Discipline | D32: Use michelin Code
B37: Phase | D37: Detailed Design | E37: - | F37: DDD
D38: For Construction | E38: - | F38: IFC
D39: As-built | E39: - | F39: ASB
B42: Revision | D42: Basic & Detail Design & Bidding & Permit
D43: A, B, C, ….
B45: Notes | D45: กรณีเอาแบบ Detailed Design มาทำรายละเอียดเพิ่มเพื่อออก Permit ให้เติม -P ไว้ด้านหลัง (น่าจะมีแค่แบบ Architect)

Sheet Subcover
A1: LMC PF1 ROR PROJECT LAEM CHABANG CHONBURI, THAILAND
B4: Drawing List
B21: 0. CIVIL WORKS
A46: LMC PF1 ROR PROJECT LAEM CHABANG CHONBURI, THAILAND
B66: 1. ARCHITECTURAL WORKS
A91: LMC PF1 ROR PROJECT LAEM CHABANG CHONBURI, THAILAND
B111: 2. STRUCTURAL WORKS
A136: LMC PF1 ROR PROJECT LAEM CHABANG CHONBURI, THAILAND
B156: 3. MECHANICAL WORKS
A181: LMC PF1 ROR PROJECT LAEM CHABANG CHONBURI, THAILAND
B201: 4. ELECTRICAL WORKS
