Workbook
Name _56F9DC9755BA473782653E2940F9FormId: "s2k3z4RsN0aT_xQVWKipwHbfHK-uxf1CjVfJxy5sJaxUQ0NaVEk3NllNTU0wNEwyS1ZLWFhKRzExSCQlQCN0PWcu"
Name _56F9DC9755BA473782653E2940F9ResponseSheet: "Form1"
Name _56F9DC9755BA473782653E2940F9SourceDocId: "{5ed865d2-441e-478a-a642-bc8736023fe2}"

Sheet Cover Page
A1: Metric Consulting Engineers & Architects Co.,Ltd. | G1: Document Number: | H1: Document Type: | I1: Discipline:
G2: TP-BM-005 | H2: TEMPLATE | I2: BIM
G3: Revision: | H3: Issue Date: | I3: Author:
B4: Metric Consulting Engineers & Architects Co.,Ltd. | G4: 00 | H4: 17-SEP-2025 | I4: PPK
B7: CLASH SUMMARY REPORT
B37: REVISIONS
B39: Rev. | C39: Date | D39: Created by | E39: Reviewed by | F39: Approved by | G39: Revision Details
B40: 00 | C40: 45917 | D40: PPK | E40: PKP | F40: PCP | G40: First issue

Sheet Clash Summary
B1: CLASH SUMMARY REPORT
B2: Project | C2: : SAMURAI CARGILL (PDPIIB)
B3: Client | C3: : Cargill Meats Thailand
B4: Report Date | C4: : 18 / 05 / 2026
B6: Current Clash by Priority | G6: Clash Status
G7: FP2 Building | H7: CI | I7: ST | J7: AR | K7: ME | L7: EE | M7: MAJOR | N7: MINOR | P7: Design Pending Issue
G8: NEW | H8: =COUNTIFS('FP2'!H:H,"NEW",'FP2'!I:I,"CI") -> 0 | I8: =COUNTIFS('FP2'!H:H,"NEW",'FP2'!I:I,"ST") -> 0 | J8: =COUNTIFS('FP2'!H:H,"NEW",'FP2'!I:I,"AR") -> 0 | K8: =COUNTIFS('FP2'!H:H,"NEW",'FP2'!I:I,"ME") -> 0 | L8: =COUNTIFS('FP2'!H:H,"NEW",'FP2'!I:I,"ME") -> 0 | M8: =COUNTIFS('FP2'!D:D,"MAJOR",'FP2'!H:H,"NEW") -> 0 | N8: =COUNTIFS('FP2'!D:D,"MINOR",'FP2'!H:H,"NEW") -> 0 | P8: 1.Note 1
G9: ACTIVE | H9: =COUNTIFS('FP2'!H:H,"ACTIVE",'FP2'!I:I,"CI") -> 0 | I9: =COUNTIFS('FP2'!H:H,"ACTIVE",'FP2'!I:I,"ST") -> 0 | J9: =COUNTIFS('FP2'!H:H,"ACTIVE",'FP2'!I:I,"AR") -> 0 | K9: =COUNTIFS('FP2'!H:H,"ACTIVE",'FP2'!I:I,"ME") -> 0 | L9: =COUNTIFS('FP2'!H:H,"ACTIVE",'FP2'!I:I,"ME") -> 0 | M9: =COUNTIFS('FP2'!D:D,"MAJOR",'FP2'!H:H,"ACTIVE") -> 0 | N9: =COUNTIFS('FP2'!D:D,"MINOR",'FP2'!H:H,"ACTIVE") -> 0 | P9: 2.Note 2
G10: PENDING | H10: =COUNTIFS('FP2'!H:H,"ACTIVE",'FP2'!I:I,"CI") -> 0 | I10: =COUNTIFS('FP2'!H:H,"PENDING",'FP2'!I:I,"ST") -> 0 | J10: =COUNTIFS('FP2'!H:H,"PENDING",'FP2'!I:I,"AR") -> 0 | K10: =COUNTIFS('FP2'!H:H,"PENDING",'FP2'!I:I,"ME") -> 0 | L10: =COUNTIFS('FP2'!H:H,"PENDING",'FP2'!I:I,"ME") -> 0 | M10: =COUNTIFS('FP2'!D:D,"MAJOR",'FP2'!H:H,"PENDING") -> 0 | N10: =COUNTIFS('FP2'!D:D,"MINOR",'FP2'!H:H,"PENDING") -> 0 | P10: 3.Note 3
G11: RESOLVED | H11: =COUNTIFS('FP2'!H:H,"RESOLVED",'FP2'!I:I,"CI") -> 0 | I11: =COUNTIFS('FP2'!H:H,"RESOLVED",'FP2'!I:I,"ST") -> 0 | J11: =COUNTIFS('FP2'!H:H,"RESOLVED",'FP2'!I:I,"AR") -> 1 | K11: =COUNTIFS('FP2'!H:H,"RESOLVED",'FP2'!I:I,"ME") -> 0 | L11: =COUNTIFS('FP2'!H:H,"RESOLVED",'FP2'!I:I,"ME") -> 0 | M11: =COUNTIFS('FP2'!D:D,"MAJOR",'FP2'!H:H,"RESOLVED") -> 0 | N11: =COUNTIFS('FP2'!D:D,"MINOR",'FP2'!H:H,"RESOLVED") -> 0
J12: Total | M12: =SUM(M8:M11) -> 0 | N12: =SUM(N8:N11) -> 0
M13: =SUM(M12+N12) -> 0
J14: Issues Remaining | M14: =SUM(M8:M10) -> 0 | N14: =SUM(N8:N10) -> 0
G18: CCS Building | H18: CI | I18: ST | J18: AR | K18: ME | L18: EE | M18: MAJOR | N18: MINOR | P18: Design Pending Issue
G19: NEW | H19: =COUNTIFS(CCS!H:H,"NEW",CCS!I:I,"CI") -> 0 | I19: =COUNTIFS(CCS!H:H,"NEW",CCS!I:I,"ST") -> 0 | J19: =COUNTIFS(CCS!H:H,"NEW",CCS!I:I,"AR") -> 0 | K19: =COUNTIFS(CCS!H:H,"NEW",CCS!I:I,"ME") -> 0 | L19: =COUNTIFS(CCS!H:H,"NEW",CCS!I:I,"EE") -> 0 | M19: =COUNTIFS(CCS!D:D,"MAJOR",CCS!H:H,"NEW") -> 0 | N19: =COUNTIFS(CCS!D:D,"MINOR",CCS!H:H,"NEW") -> 0 | P19: 1.Note 1
G20: ACTIVE | H20: =COUNTIFS(CCS!H:H,"ACTIVE",CCS!I:I,"CI") -> 0 | I20: =COUNTIFS(CCS!H:H,"ACTIVE",CCS!I:I,"ST") -> 0 | J20: =COUNTIFS(CCS!H:H,"ACTIVE",CCS!I:I,"AR") -> 0 | K20: =COUNTIFS(CCS!H:H,"ACTIVE",CCS!I:I,"ME") -> 0 | L20: =COUNTIFS(CCS!H:H,"ACTIVE",CCS!I:I,"EE") -> 0 | M20: =COUNTIFS(CCS!D:D,"MAJOR",CCS!H:H,"ACTIVE") -> 0 | N20: =COUNTIFS(CCS!D:D,"MINOR",CCS!H:H,"ACTIVE") -> 0 | P20: 2.Note 2
G21: PENDING | H21: =COUNTIFS(CCS!H:H,"PENDING",CCS!I:I,"CI") -> 0 | I21: =COUNTIFS(CCS!H:H,"PENDING",CCS!I:I,"ST") -> 0 | J21: =COUNTIFS(CCS!H:H,"PENDING",CCS!I:I,"AR") -> 0 | K21: =COUNTIFS(CCS!H:H,"PENDING",CCS!I:I,"ME") -> 0 | L21: =COUNTIFS(CCS!H:H,"PENDING",CCS!I:I,"EE") -> 0 | M21: =COUNTIFS(CCS!D:D,"MAJOR",CCS!H:H,"PENDING") -> 0 | N21: =COUNTIFS(CCS!D:D,"MINOR",CCS!H:H,"PENDING") -> 0 | P21: 3.Note 3
G22: RESOLVED | H22: =COUNTIFS(CCS!H:H,"RESOLVED",CCS!I:I,"CI") -> 0 | I22: =COUNTIFS(CCS!H:H,"RESOLVED",CCS!I:I,"ST") -> 0 | J22: =COUNTIFS(CCS!H:H,"RESOLVED",CCS!I:I,"AR") -> 0 | K22: =COUNTIFS(CCS!H:H,"RESOLVED",CCS!I:I,"ME") -> 0 | L22: =COUNTIFS(CCS!H:H,"RESOLVED",CCS!I:I,"EE") -> 0 | M22: =COUNTIFS(CCS!D:D,"MAJOR",CCS!H:H,"RESOLVED") -> 0 | N22: =COUNTIFS(CCS!D:D,"MINOR",CCS!H:H,"RESOLVED") -> 0
J23: Total | M23: =SUM(M19:M22) -> 0 | N23: =SUM(N19:N22) -> 0
M24: =SUM(M23+N23) -> 0
B25: Clash Resolved | J25: Issues Remaining | M25: =SUM(M19:M21) -> 0 | N25: =SUM(N19:N21) -> 0
G28: Outside Building | H28: CI | I28: ST | J28: AR | K28: ME | L28: EE | M28: MAJOR | N28: MINOR | P28: Design Pending Issue
G29: NEW | H29: =COUNTIFS('Outside building'!H:H,"NEW",'Outside building'!I:I,"CI") -> 0 | I29: =COUNTIFS('Outside building'!I:I,"NEW",'Outside building'!J:J,"ST") -> 0 | J29: =COUNTIFS('Outside building'!J:J,"NEW",'Outside building'!K:K,"AR") -> 0 | K29: =COUNTIFS('Outside building'!K:K,"NEW",'Outside building'!L:L,"ME") -> 0 | L29: =COUNTIFS('Outside building'!L:L,"NEW",'Outside building'!M:M,"EE") -> 0 | M29: =COUNTIFS('Outside building'!D:D,"MAJOR",'Outside building'!H:H,"NEW") -> 0 | N29: =COUNTIFS('Outside building'!D:D,"MINOR",'Outside building'!H:H,"NEW") -> 0 | P29: 1.Note 1
G30: ACTIVE | H30: =COUNTIFS('Outside building'!H:H,"NEW",'Outside building'!I:I,"CI") -> 0 | I30: =COUNTIFS('Outside building'!I:I,"NEW",'Outside building'!J:J,"ST") -> 0 | J30: =COUNTIFS('Outside building'!J:J,"NEW",'Outside building'!K:K,"AR") -> 0 | K30: =COUNTIFS('Outside building'!K:K,"NEW",'Outside building'!L:L,"ME") -> 0 | L30: =COUNTIFS('Outside building'!L:L,"NEW",'Outside building'!M:M,"EE") -> 0 | M30: =COUNTIFS('Outside building'!D:D,"MAJOR",'Outside building'!H:H,"ACTIVE") -> 0 | N30: =COUNTIFS('Outside building'!D:D,"MINOR",'Outside building'!H:H,"ACTIVE") -> 0 | P30: 2.Note 2
G31: PENDING | H31: =COUNTIFS('Outside building'!H:H,"NEW",'Outside building'!I:I,"CI") -> 0 | I31: =COUNTIFS('Outside building'!I:I,"NEW",'Outside building'!J:J,"ST") -> 0 | J31: =COUNTIFS('Outside building'!J:J,"NEW",'Outside building'!K:K,"AR") -> 0 | K31: =COUNTIFS('Outside building'!K:K,"NEW",'Outside building'!L:L,"ME") -> 0 | L31: =COUNTIFS('Outside building'!L:L,"NEW",'Outside building'!M:M,"EE") -> 0 | M31: =COUNTIFS('Outside building'!D:D,"MAJOR",'Outside building'!H:H,"PENDING") -> 0 | N31: =COUNTIFS('Outside building'!D:D,"MINOR",'Outside building'!H:H,"PENDING") -> 0 | P31: 3.Note 3
G32: RESOLVED | H32: =COUNTIFS('Outside building'!H:H,"NEW",'Outside building'!I:I,"CI") -> 0 | I32: =COUNTIFS('Outside building'!I:I,"NEW",'Outside building'!J:J,"ST") -> 0 | J32: =COUNTIFS('Outside building'!J:J,"NEW",'Outside building'!K:K,"AR") -> 0 | K32: =COUNTIFS('Outside building'!K:K,"NEW",'Outside building'!L:L,"ME") -> 0 | L32: =COUNTIFS('Outside building'!L:L,"NEW",'Outside building'!M:M,"EE") -> 0 | M32: =COUNTIFS('Outside building'!D:D,"MAJOR",'Outside building'!H:H,"RESOLVED") -> 0 | N32: =COUNTIFS('Outside building'!D:D,"MINOR",'Outside building'!H:H,"RESOLVED") -> 0
J33: Total | M33: =SUM(M29:M32) -> 0 | N33: =SUM(N29:N32) -> 0
M34: =SUM(M33+N33) -> 0
J35: Issues Remaining | M35: =SUM(M29:M31) -> 0 | N35: =SUM(N29:N31) -> 0

Sheet FP2
A2: CLASH REPORT : 100% Basic Design | S2: Clash summary
S3: NEW | T3: =COUNTIF(H:H,"NEW") -> 1
A4: ='Clash Summary'!B2 -> Project | B4: ='Clash Summary'!C2 -> : SAMURAI CARGILL (PDPIIB) | S4: ACTIVE | T4: =COUNTIF(H:H,"ACTIVE") -> 0
A5: ='Clash Summary'!B3 -> Client | B5: ='Clash Summary'!C3 -> : Cargill Meats Thailand | S5: RESOLVED | T5: =COUNTIF(H:H,"RESOLVED") -> 1
A6: ='Clash Summary'!B4 -> Report Date | B6: ='Clash Summary'!C4 -> : 18 / 05 / 2026 | S6: PENDING | T6: =COUNTIF(H:H,"PENDING") -> 0
S7: Total | T7: =SUM(T3:T6) -> 2
A8: Item | B8: Folder [In Viewpoint] | C8: Viewpoint Title | D8: Priority | E8: Discipline | F8: Date Found | G8: Image | H8: Clash Status | I8: Resp. by | J8: For Designer
J9: Resolved | K9: Design Pending | L9: Issue shall be resolve on cons. phase | M9: Note | N9: Image After Resolved
A10: 1 | B10: VISUAL CHECK | C10: Template | D10: =RIGHT(C10,LEN(C10)-FIND("@",SUBSTITUTE(C10,"_","@",LEN(C10)-LEN(SUBSTITUTE(C10,"_",""))))) -> #VALUE! | E10: =MID(C10, FIND("_", C10, FIND("_", C10) + 1) + 1, FIND("_", C10, FIND("_", C10, FIND("_", C10) + 1) + 1) - FIND("_", C10, FIND("_", C10) + 1)- 1) -> #VALUE! | H10: RESOLVED | I10: AR | J10: FALSE | K10: FALSE | L10: FALSE
A11: 2 | B11: CLASH CHECK | C11: Template | H11: NEW | J11: FALSE | K11: FALSE | L11: FALSE

Sheet CCS
A2: CLASH REPORT : 100% Basic Design | S2: Clash summary
S3: NEW | T3: =COUNTIF(H:H,"NEW") -> 5
A4: ='Clash Summary'!B2 -> Project | B4: ='Clash Summary'!C2 -> : SAMURAI CARGILL (PDPIIB) | S4: ACTIVE | T4: =COUNTIF(H:H,"ACTIVE") -> 0
A5: ='Clash Summary'!B3 -> Client | B5: ='Clash Summary'!C3 -> : Cargill Meats Thailand | S5: RESOLVED | T5: =COUNTIF(H:H,"RESOLVED") -> 0
A6: ='Clash Summary'!B4 -> Report Date | B6: ='Clash Summary'!C4 -> : 18 / 05 / 2026 | S6: PENDING | T6: =COUNTIF(H:H,"PENDING") -> 0
S7: Total | T7: =SUM(T3:T6) -> 5
A8: Item | B8: Folder [In Viewpoint] | C8: Viewpoint Title | D8: Priority | E8: Discipline | F8: Date Found | G8: Image | H8: Clash Status | I8: Resp. by | J8: For Designer | N8: Image After Resolved
J9: Resolved | K9: Design Pending | L9: Issue shall be resolve on cons. phase | M9: Note
A10: 1 | B10: VISUAL CHECK | C10: V015_AR_Guard rail obstructs door SPD | G10: #VALUE! | H10: NEW | J10: FALSE | K10: FALSE | L10: FALSE
A11: 2 | B11: VISUAL CHECK | C11: V016_AR_Need reailing? | D11: =RIGHT(C11,LEN(C11)-FIND("@",SUBSTITUTE(C11,"_","@",LEN(C11)-LEN(SUBSTITUTE(C11,"_",""))))) -> Need reailing? | E11: =LEFT(C11, FIND("_", C11) - 1) -> V016 | G11: #VALUE! | H11: NEW | J11: FALSE | K11: FALSE | L11: FALSE
A12: 3 | B12: VISUAL CHECK | C12: V019_AR/ST_ตรวจสอบความเรียบร้อยโมเดล canopy | D12: =RIGHT(C12,LEN(C12)-FIND("@",SUBSTITUTE(C12,"_","@",LEN(C12)-LEN(SUBSTITUTE(C12,"_",""))))) -> ตรวจสอบความเรียบร้อยโมเดล canopy | E12: =LEFT(C12, FIND("_", C12) - 1) -> V019 | G12: #VALUE! | H12: NEW | J12: FALSE | K12: FALSE | L12: FALSE
A13: 4 | B13: VISUAL CHECK | C13: V020_MEP_Recheck ความเรียบร้อยมเดล | D13: =RIGHT(C13,LEN(C13)-FIND("@",SUBSTITUTE(C13,"_","@",LEN(C13)-LEN(SUBSTITUTE(C13,"_",""))))) -> Recheck ความเรียบร้อยมเดล | E13: =LEFT(C13, FIND("_", C13) - 1) -> V020 | G13: #VALUE! | H13: NEW | J13: FALSE | K13: FALSE | L13: FALSE
A14: 5 | B14: VISUAL CHECK | C14: V021_ME_Check แนวท่อเชื่อม vs AHU | D14: =RIGHT(C14,LEN(C14)-FIND("@",SUBSTITUTE(C14,"_","@",LEN(C14)-LEN(SUBSTITUTE(C14,"_",""))))) -> Check แนวท่อเชื่อม vs AHU | E14: =LEFT(C14, FIND("_", C14) - 1) -> V021 | G14: #VALUE! | H14: NEW | J14: FALSE | K14: FALSE | L14: FALSE
D15: =RIGHT(C15,LEN(C15)-FIND("@",SUBSTITUTE(C15,"_","@",LEN(C15)-LEN(SUBSTITUTE(C15,"_",""))))) -> #VALUE! | E15: =MID(C15, FIND("_", C15, FIND("_", C15) + 1) + 1, FIND("_", C15, FIND("_", C15, FIND("_", C15) + 1) + 1) - FIND("_", C15, FIND("_", C15) + 1)- 1) -> #VALUE! | J15: FALSE | K15: FALSE | L15: FALSE
D16: =RIGHT(C16,LEN(C16)-FIND("@",SUBSTITUTE(C16,"_","@",LEN(C16)-LEN(SUBSTITUTE(C16,"_",""))))) -> #VALUE! | E16: =MID(C16, FIND("_", C16, FIND("_", C16) + 1) + 1, FIND("_", C16, FIND("_", C16, FIND("_", C16) + 1) + 1) - FIND("_", C16, FIND("_", C16) + 1)- 1) -> #VALUE! | J16: FALSE | K16: FALSE | L16: FALSE
D17: =RIGHT(C17,LEN(C17)-FIND("@",SUBSTITUTE(C17,"_","@",LEN(C17)-LEN(SUBSTITUTE(C17,"_",""))))) -> #VALUE! | E17: =MID(C17, FIND("_", C17, FIND("_", C17) + 1) + 1, FIND("_", C17, FIND("_", C17, FIND("_", C17) + 1) + 1) - FIND("_", C17, FIND("_", C17) + 1)- 1) -> #VALUE! | J17: FALSE | K17: FALSE | L17: FALSE
D18: =RIGHT(C18,LEN(C18)-FIND("@",SUBSTITUTE(C18,"_","@",LEN(C18)-LEN(SUBSTITUTE(C18,"_",""))))) -> #VALUE! | E18: =MID(C18, FIND("_", C18, FIND("_", C18) + 1) + 1, FIND("_", C18, FIND("_", C18, FIND("_", C18) + 1) + 1) - FIND("_", C18, FIND("_", C18) + 1)- 1) -> #VALUE! | J18: FALSE | K18: FALSE | L18: FALSE
D19: =RIGHT(C19,LEN(C19)-FIND("@",SUBSTITUTE(C19,"_","@",LEN(C19)-LEN(SUBSTITUTE(C19,"_",""))))) -> #VALUE! | E19: =MID(C19, FIND("_", C19, FIND("_", C19) + 1) + 1, FIND("_", C19, FIND("_", C19, FIND("_", C19) + 1) + 1) - FIND("_", C19, FIND("_", C19) + 1)- 1) -> #VALUE! | J19: FALSE | K19: FALSE | L19: FALSE
D20: =RIGHT(C20,LEN(C20)-FIND("@",SUBSTITUTE(C20,"_","@",LEN(C20)-LEN(SUBSTITUTE(C20,"_",""))))) -> #VALUE! | E20: =MID(C20, FIND("_", C20, FIND("_", C20) + 1) + 1, FIND("_", C20, FIND("_", C20, FIND("_", C20) + 1) + 1) - FIND("_", C20, FIND("_", C20) + 1)- 1) -> #VALUE! | J20: FALSE | K20: FALSE | L20: FALSE
D21: =RIGHT(C21,LEN(C21)-FIND("@",SUBSTITUTE(C21,"_","@",LEN(C21)-LEN(SUBSTITUTE(C21,"_",""))))) -> #VALUE! | E21: =MID(C21, FIND("_", C21, FIND("_", C21) + 1) + 1, FIND("_", C21, FIND("_", C21, FIND("_", C21) + 1) + 1) - FIND("_", C21, FIND("_", C21) + 1)- 1) -> #VALUE! | J21: FALSE | K21: FALSE | L21: FALSE
D22: =RIGHT(C22,LEN(C22)-FIND("@",SUBSTITUTE(C22,"_","@",LEN(C22)-LEN(SUBSTITUTE(C22,"_",""))))) -> #VALUE! | E22: =LEFT(C22, FIND("_", C22) - 1) -> #VALUE! | J22: FALSE | K22: FALSE | L22: FALSE
D23: =RIGHT(C23,LEN(C23)-FIND("@",SUBSTITUTE(C23,"_","@",LEN(C23)-LEN(SUBSTITUTE(C23,"_",""))))) -> #VALUE! | E23: =LEFT(C23, FIND("_", C23) - 1) -> #VALUE! | J23: FALSE | K23: FALSE | L23: FALSE
D24: =RIGHT(C24,LEN(C24)-FIND("@",SUBSTITUTE(C24,"_","@",LEN(C24)-LEN(SUBSTITUTE(C24,"_",""))))) -> #VALUE! | E24: =LEFT(C24, FIND("_", C24) - 1) -> #VALUE! | J24: FALSE | K24: FALSE | L24: FALSE
D25: =RIGHT(C25,LEN(C25)-FIND("@",SUBSTITUTE(C25,"_","@",LEN(C25)-LEN(SUBSTITUTE(C25,"_",""))))) -> #VALUE! | E25: =LEFT(C25, FIND("_", C25) - 1) -> #VALUE! | J25: FALSE | K25: FALSE | L25: FALSE
D26: =RIGHT(C26,LEN(C26)-FIND("@",SUBSTITUTE(C26,"_","@",LEN(C26)-LEN(SUBSTITUTE(C26,"_",""))))) -> #VALUE! | E26: =LEFT(C26, FIND("_", C26) - 1) -> #VALUE! | J26: FALSE | K26: FALSE | L26: FALSE
D27: =RIGHT(C27,LEN(C27)-FIND("@",SUBSTITUTE(C27,"_","@",LEN(C27)-LEN(SUBSTITUTE(C27,"_",""))))) -> #VALUE! | E27: =LEFT(C27, FIND("_", C27) - 1) -> #VALUE! | J27: FALSE | K27: FALSE | L27: FALSE
D28: =RIGHT(C28,LEN(C28)-FIND("@",SUBSTITUTE(C28,"_","@",LEN(C28)-LEN(SUBSTITUTE(C28,"_",""))))) -> #VALUE! | E28: =LEFT(C28, FIND("_", C28) - 1) -> #VALUE! | J28: FALSE | K28: FALSE | L28: FALSE
D29: =RIGHT(C29,LEN(C29)-FIND("@",SUBSTITUTE(C29,"_","@",LEN(C29)-LEN(SUBSTITUTE(C29,"_",""))))) -> #VALUE! | E29: =LEFT(C29, FIND("_", C29) - 1) -> #VALUE! | J29: FALSE | K29: FALSE | L29: FALSE
D30: =RIGHT(C30,LEN(C30)-FIND("@",SUBSTITUTE(C30,"_","@",LEN(C30)-LEN(SUBSTITUTE(C30,"_",""))))) -> #VALUE! | E30: =LEFT(C30, FIND("_", C30) - 1) -> #VALUE! | J30: FALSE | K30: FALSE | L30: FALSE
D31: =RIGHT(C31,LEN(C31)-FIND("@",SUBSTITUTE(C31,"_","@",LEN(C31)-LEN(SUBSTITUTE(C31,"_",""))))) -> #VALUE! | E31: =LEFT(C31, FIND("_", C31) - 1) -> #VALUE! | J31: FALSE | K31: FALSE | L31: FALSE
D32: =RIGHT(C32,LEN(C32)-FIND("@",SUBSTITUTE(C32,"_","@",LEN(C32)-LEN(SUBSTITUTE(C32,"_",""))))) -> #VALUE! | E32: =LEFT(C32, FIND("_", C32) - 1) -> #VALUE! | J32: FALSE | K32: FALSE | L32: FALSE
D33: =RIGHT(C33,LEN(C33)-FIND("@",SUBSTITUTE(C33,"_","@",LEN(C33)-LEN(SUBSTITUTE(C33,"_",""))))) -> #VALUE! | E33: =LEFT(C33, FIND("_", C33) - 1) -> #VALUE! | J33: FALSE | K33: FALSE | L33: FALSE
... D50: =RIGHT(C50,LEN(C50)-FIND("@",SUBSTITUTE(C50,"_","@",LEN(C50)-LEN(SUBSTITUTE(C50,"_",""))))) -> #VALUE! | E50: =LEFT(C50, FIND("_", C50) - 1) -> #VALUE! | J50: FALSE | K50: FALSE | L50: FALSE
D51: =RIGHT(C51,LEN(C51)-FIND("@",SUBSTITUTE(C51,"_","@",LEN(C51)-LEN(SUBSTITUTE(C51,"_",""))))) -> #VALUE! | E51: =MID(C51, FIND("_", C51, FIND("_", C51) + 1) + 1, FIND("_", C51, FIND("_", C51, FIND("_", C51) + 1) + 1) - FIND("_", C51, FIND("_", C51) + 1)- 1) -> #VALUE! | J51: FALSE | K51: FALSE | L51: FALSE
D52: =RIGHT(C52,LEN(C52)-FIND("@",SUBSTITUTE(C52,"_","@",LEN(C52)-LEN(SUBSTITUTE(C52,"_",""))))) -> #VALUE! | E52: =MID(C52, FIND("_", C52, FIND("_", C52) + 1) + 1, FIND("_", C52, FIND("_", C52, FIND("_", C52) + 1) + 1) - FIND("_", C52, FIND("_", C52) + 1)- 1) -> #VALUE! | J52: FALSE | K52: FALSE | L52: FALSE
D53: =RIGHT(C53,LEN(C53)-FIND("@",SUBSTITUTE(C53,"_","@",LEN(C53)-LEN(SUBSTITUTE(C53,"_",""))))) -> #VALUE! | E53: =MID(C53, FIND("_", C53, FIND("_", C53) + 1) + 1, FIND("_", C53, FIND("_", C53, FIND("_", C53) + 1) + 1) - FIND("_", C53, FIND("_", C53) + 1)- 1) -> #VALUE! | J53: FALSE | K53: FALSE | L53: FALSE
D54: =RIGHT(C54,LEN(C54)-FIND("@",SUBSTITUTE(C54,"_","@",LEN(C54)-LEN(SUBSTITUTE(C54,"_",""))))) -> #VALUE! | E54: =MID(C54, FIND("_", C54, FIND("_", C54) + 1) + 1, FIND("_", C54, FIND("_", C54, FIND("_", C54) + 1) + 1) - FIND("_", C54, FIND("_", C54) + 1)- 1) -> #VALUE! | J54: FALSE | K54: FALSE | L54: FALSE
D55: =RIGHT(C55,LEN(C55)-FIND("@",SUBSTITUTE(C55,"_","@",LEN(C55)-LEN(SUBSTITUTE(C55,"_",""))))) -> #VALUE! | E55: =MID(C55, FIND("_", C55, FIND("_", C55) + 1) + 1, FIND("_", C55, FIND("_", C55, FIND("_", C55) + 1) + 1) - FIND("_", C55, FIND("_", C55) + 1)- 1) -> #VALUE! | J55: FALSE | K55: FALSE | L55: FALSE
D56: =RIGHT(C56,LEN(C56)-FIND("@",SUBSTITUTE(C56,"_","@",LEN(C56)-LEN(SUBSTITUTE(C56,"_",""))))) -> #VALUE! | E56: =MID(C56, FIND("_", C56, FIND("_", C56) + 1) + 1, FIND("_", C56, FIND("_", C56, FIND("_", C56) + 1) + 1) - FIND("_", C56, FIND("_", C56) + 1)- 1) -> #VALUE! | J56: FALSE | K56: FALSE | L56: FALSE
D57: =RIGHT(C57,LEN(C57)-FIND("@",SUBSTITUTE(C57,"_","@",LEN(C57)-LEN(SUBSTITUTE(C57,"_",""))))) -> #VALUE! | E57: =MID(C57, FIND("_", C57, FIND("_", C57) + 1) + 1, FIND("_", C57, FIND("_", C57, FIND("_", C57) + 1) + 1) - FIND("_", C57, FIND("_", C57) + 1)- 1) -> #VALUE! | J57: FALSE | K57: FALSE | L57: FALSE
...

Sheet Outside building
A2: CLASH REPORT : 100% Basic Design | S2: Clash summary
S3: NEW | T3: =COUNTIF(H:H,"NEW") -> 0
A4: ='Clash Summary'!B2 -> Project | B4: ='Clash Summary'!C2 -> : SAMURAI CARGILL (PDPIIB) | S4: ACTIVE | T4: =COUNTIF(H:H,"ACTIVE") -> 0
A5: ='Clash Summary'!B3 -> Client | B5: ='Clash Summary'!C3 -> : Cargill Meats Thailand | S5: RESOLVED | T5: =COUNTIF(H:H,"RESOLVED") -> 0
A6: ='Clash Summary'!B4 -> Report Date | B6: ='Clash Summary'!C4 -> : 18 / 05 / 2026 | S6: PENDING | T6: =COUNTIF(H:H,"PENDING") -> 0
S7: Total | T7: =SUM(T3:T6) -> 0
A8: Item | B8: Folder [In Viewpoint] | C8: Viewpoint Title | D8: Priority | E8: Discipline | F8: Date Found | G8: Image | H8: Clash Status | I8: Resp. by | J8: For Designer | N8: Image After Resolved
J9: Resolved | K9: Design Pending | L9: Issue shall be resolve on cons. phase | M9: Note
A10: =LEFT(C10, FIND("_", C10) - 1) -> #VALUE! | D10: =RIGHT(C10,LEN(C10)-FIND("@",SUBSTITUTE(C10,"_","@",LEN(C10)-LEN(SUBSTITUTE(C10,"_",""))))) -> #VALUE! | E10: =MID(C10, FIND("_", C10, FIND("_", C10) + 1) + 1, FIND("_", C10, FIND("_", C10, FIND("_", C10) + 1) + 1) - FIND("_", C10, FIND("_", C10) + 1)- 1) -> #VALUE! | J10: FALSE | K10: FALSE | L10: FALSE
A11: =LEFT(C11, FIND("_", C11) - 1) -> #VALUE! | D11: =RIGHT(C11,LEN(C11)-FIND("@",SUBSTITUTE(C11,"_","@",LEN(C11)-LEN(SUBSTITUTE(C11,"_",""))))) -> #VALUE! | E11: =MID(C11, FIND("_", C11, FIND("_", C11) + 1) + 1, FIND("_", C11, FIND("_", C11, FIND("_", C11) + 1) + 1) - FIND("_", C11, FIND("_", C11) + 1)- 1) -> #VALUE! | J11: FALSE | K11: FALSE | L11: FALSE
A12: =LEFT(C12, FIND("_", C12) - 1) -> #VALUE! | D12: =RIGHT(C12,LEN(C12)-FIND("@",SUBSTITUTE(C12,"_","@",LEN(C12)-LEN(SUBSTITUTE(C12,"_",""))))) -> #VALUE! | E12: =MID(C12, FIND("_", C12, FIND("_", C12) + 1) + 1, FIND("_", C12, FIND("_", C12, FIND("_", C12) + 1) + 1) - FIND("_", C12, FIND("_", C12) + 1)- 1) -> #VALUE! | J12: FALSE | K12: FALSE | L12: FALSE
A13: =LEFT(C13, FIND("_", C13) - 1) -> #VALUE! | D13: =RIGHT(C13,LEN(C13)-FIND("@",SUBSTITUTE(C13,"_","@",LEN(C13)-LEN(SUBSTITUTE(C13,"_",""))))) -> #VALUE! | E13: =MID(C13, FIND("_", C13, FIND("_", C13) + 1) + 1, FIND("_", C13, FIND("_", C13, FIND("_", C13) + 1) + 1) - FIND("_", C13, FIND("_", C13) + 1)- 1) -> #VALUE! | J13: FALSE | K13: FALSE | L13: FALSE
A14: =LEFT(C14, FIND("_", C14) - 1) -> #VALUE! | D14: =RIGHT(C14,LEN(C14)-FIND("@",SUBSTITUTE(C14,"_","@",LEN(C14)-LEN(SUBSTITUTE(C14,"_",""))))) -> #VALUE! | E14: =MID(C14, FIND("_", C14, FIND("_", C14) + 1) + 1, FIND("_", C14, FIND("_", C14, FIND("_", C14) + 1) + 1) - FIND("_", C14, FIND("_", C14) + 1)- 1) -> #VALUE! | J14: FALSE | K14: FALSE | L14: FALSE
A15: =LEFT(C15, FIND("_", C15) - 1) -> #VALUE! | D15: =RIGHT(C15,LEN(C15)-FIND("@",SUBSTITUTE(C15,"_","@",LEN(C15)-LEN(SUBSTITUTE(C15,"_",""))))) -> #VALUE! | E15: =MID(C15, FIND("_", C15, FIND("_", C15) + 1) + 1, FIND("_", C15, FIND("_", C15, FIND("_", C15) + 1) + 1) - FIND("_", C15, FIND("_", C15) + 1)- 1) -> #VALUE! | J15: FALSE | K15: FALSE | L15: FALSE
A16: =LEFT(C16, FIND("_", C16) - 1) -> #VALUE! | D16: =RIGHT(C16,LEN(C16)-FIND("@",SUBSTITUTE(C16,"_","@",LEN(C16)-LEN(SUBSTITUTE(C16,"_",""))))) -> #VALUE! | E16: =LEFT(C16, FIND("_", C16) - 1) -> #VALUE! | J16: FALSE | K16: FALSE | L16: FALSE
A17: =LEFT(C17, FIND("_", C17) - 1) -> #VALUE! | D17: =RIGHT(C17,LEN(C17)-FIND("@",SUBSTITUTE(C17,"_","@",LEN(C17)-LEN(SUBSTITUTE(C17,"_",""))))) -> #VALUE! | E17: =LEFT(C17, FIND("_", C17) - 1) -> #VALUE! | J17: FALSE | K17: FALSE | L17: FALSE
A18: =LEFT(C18, FIND("_", C18) - 1) -> #VALUE! | D18: =RIGHT(C18,LEN(C18)-FIND("@",SUBSTITUTE(C18,"_","@",LEN(C18)-LEN(SUBSTITUTE(C18,"_",""))))) -> #VALUE! | E18: =LEFT(C18, FIND("_", C18) - 1) -> #VALUE! | J18: FALSE | K18: FALSE | L18: FALSE
A19: =LEFT(C19, FIND("_", C19) - 1) -> #VALUE! | D19: =RIGHT(C19,LEN(C19)-FIND("@",SUBSTITUTE(C19,"_","@",LEN(C19)-LEN(SUBSTITUTE(C19,"_",""))))) -> #VALUE! | E19: =LEFT(C19, FIND("_", C19) - 1) -> #VALUE! | J19: FALSE | K19: FALSE | L19: FALSE
A20: =LEFT(C20, FIND("_", C20) - 1) -> #VALUE! | D20: =RIGHT(C20,LEN(C20)-FIND("@",SUBSTITUTE(C20,"_","@",LEN(C20)-LEN(SUBSTITUTE(C20,"_",""))))) -> #VALUE! | E20: =LEFT(C20, FIND("_", C20) - 1) -> #VALUE! | J20: FALSE | K20: FALSE | L20: FALSE
A21: =LEFT(C21, FIND("_", C21) - 1) -> #VALUE! | D21: =RIGHT(C21,LEN(C21)-FIND("@",SUBSTITUTE(C21,"_","@",LEN(C21)-LEN(SUBSTITUTE(C21,"_",""))))) -> #VALUE! | E21: =LEFT(C21, FIND("_", C21) - 1) -> #VALUE! | J21: FALSE | K21: FALSE | L21: FALSE
A22: =LEFT(C22, FIND("_", C22) - 1) -> #VALUE! | D22: =RIGHT(C22,LEN(C22)-FIND("@",SUBSTITUTE(C22,"_","@",LEN(C22)-LEN(SUBSTITUTE(C22,"_",""))))) -> #VALUE! | E22: =LEFT(C22, FIND("_", C22) - 1) -> #VALUE! | J22: FALSE | K22: FALSE | L22: FALSE
A23: =LEFT(C23, FIND("_", C23) - 1) -> #VALUE! | D23: =RIGHT(C23,LEN(C23)-FIND("@",SUBSTITUTE(C23,"_","@",LEN(C23)-LEN(SUBSTITUTE(C23,"_",""))))) -> #VALUE! | E23: =MID(C23, FIND("_", C23, FIND("_", C23) + 1) + 1, FIND("_", C23, FIND("_", C23, FIND("_", C23) + 1) + 1) - FIND("_", C23, FIND("_", C23) + 1)- 1) -> #VALUE! | J23: FALSE | K23: FALSE | L23: FALSE
A24: =LEFT(C24, FIND("_", C24) - 1) -> #VALUE! | D24: =RIGHT(C24,LEN(C24)-FIND("@",SUBSTITUTE(C24,"_","@",LEN(C24)-LEN(SUBSTITUTE(C24,"_",""))))) -> #VALUE! | E24: =MID(C24, FIND("_", C24, FIND("_", C24) + 1) + 1, FIND("_", C24, FIND("_", C24, FIND("_", C24) + 1) + 1) - FIND("_", C24, FIND("_", C24) + 1)- 1) -> #VALUE! | J24: FALSE | K24: FALSE | L24: FALSE
A25: =LEFT(C25, FIND("_", C25) - 1) -> #VALUE! | D25: =RIGHT(C25,LEN(C25)-FIND("@",SUBSTITUTE(C25,"_","@",LEN(C25)-LEN(SUBSTITUTE(C25,"_",""))))) -> #VALUE! | E25: =LEFT(C25, FIND("_", C25) - 1) -> #VALUE! | J25: FALSE | K25: FALSE | L25: FALSE
A26: =LEFT(C26, FIND("_", C26) - 1) -> #VALUE! | D26: =RIGHT(C26,LEN(C26)-FIND("@",SUBSTITUTE(C26,"_","@",LEN(C26)-LEN(SUBSTITUTE(C26,"_",""))))) -> #VALUE! | E26: =LEFT(C26, FIND("_", C26) - 1) -> #VALUE! | J26: FALSE | K26: FALSE | L26: FALSE
A27: =LEFT(C27, FIND("_", C27) - 1) -> #VALUE! | D27: =RIGHT(C27,LEN(C27)-FIND("@",SUBSTITUTE(C27,"_","@",LEN(C27)-LEN(SUBSTITUTE(C27,"_",""))))) -> #VALUE! | E27: =LEFT(C27, FIND("_", C27) - 1) -> #VALUE! | J27: FALSE | K27: FALSE | L27: FALSE
A28: =LEFT(C28, FIND("_", C28) - 1) -> #VALUE! | D28: =RIGHT(C28,LEN(C28)-FIND("@",SUBSTITUTE(C28,"_","@",LEN(C28)-LEN(SUBSTITUTE(C28,"_",""))))) -> #VALUE! | E28: =LEFT(C28, FIND("_", C28) - 1) -> #VALUE! | J28: FALSE | K28: FALSE | L28: FALSE
A29: =LEFT(C29, FIND("_", C29) - 1) -> #VALUE! | D29: =RIGHT(C29,LEN(C29)-FIND("@",SUBSTITUTE(C29,"_","@",LEN(C29)-LEN(SUBSTITUTE(C29,"_",""))))) -> #VALUE! | E29: =LEFT(C29, FIND("_", C29) - 1) -> #VALUE! | J29: FALSE | K29: FALSE | L29: FALSE
A30: =LEFT(C30, FIND("_", C30) - 1) -> #VALUE! | D30: =RIGHT(C30,LEN(C30)-FIND("@",SUBSTITUTE(C30,"_","@",LEN(C30)-LEN(SUBSTITUTE(C30,"_",""))))) -> #VALUE! | E30: =LEFT(C30, FIND("_", C30) - 1) -> #VALUE! | J30: FALSE | K30: FALSE | L30: FALSE
A31: =LEFT(C31, FIND("_", C31) - 1) -> #VALUE! | D31: =RIGHT(C31,LEN(C31)-FIND("@",SUBSTITUTE(C31,"_","@",LEN(C31)-LEN(SUBSTITUTE(C31,"_",""))))) -> #VALUE! | E31: =LEFT(C31, FIND("_", C31) - 1) -> #VALUE! | J31: FALSE | K31: FALSE | L31: FALSE
A32: =LEFT(C32, FIND("_", C32) - 1) -> #VALUE! | D32: =RIGHT(C32,LEN(C32)-FIND("@",SUBSTITUTE(C32,"_","@",LEN(C32)-LEN(SUBSTITUTE(C32,"_",""))))) -> #VALUE! | E32: =LEFT(C32, FIND("_", C32) - 1) -> #VALUE! | J32: FALSE | K32: FALSE | L32: FALSE
A33: =LEFT(C33, FIND("_", C33) - 1) -> #VALUE! | D33: =RIGHT(C33,LEN(C33)-FIND("@",SUBSTITUTE(C33,"_","@",LEN(C33)-LEN(SUBSTITUTE(C33,"_",""))))) -> #VALUE! | E33: =LEFT(C33, FIND("_", C33) - 1) -> #VALUE! | J33: FALSE | K33: FALSE | L33: FALSE
A34: =LEFT(C34, FIND("_", C34) - 1) -> #VALUE! | D34: =RIGHT(C34,LEN(C34)-FIND("@",SUBSTITUTE(C34,"_","@",LEN(C34)-LEN(SUBSTITUTE(C34,"_",""))))) -> #VALUE! | E34: =LEFT(C34, FIND("_", C34) - 1) -> #VALUE! | J34: FALSE | K34: FALSE | L34: FALSE
A35: =LEFT(C35, FIND("_", C35) - 1) -> #VALUE! | D35: =RIGHT(C35,LEN(C35)-FIND("@",SUBSTITUTE(C35,"_","@",LEN(C35)-LEN(SUBSTITUTE(C35,"_",""))))) -> #VALUE! | E35: =LEFT(C35, FIND("_", C35) - 1) -> #VALUE! | J35: FALSE | K35: FALSE | L35: FALSE
A36: =LEFT(C36, FIND("_", C36) - 1) -> #VALUE! | D36: =RIGHT(C36,LEN(C36)-FIND("@",SUBSTITUTE(C36,"_","@",LEN(C36)-LEN(SUBSTITUTE(C36,"_",""))))) -> #VALUE! | E36: =LEFT(C36, FIND("_", C36) - 1) -> #VALUE! | J36: FALSE | K36: FALSE | L36: FALSE
... A50: =LEFT(C50, FIND("_", C50) - 1) -> #VALUE! | D50: =RIGHT(C50,LEN(C50)-FIND("@",SUBSTITUTE(C50,"_","@",LEN(C50)-LEN(SUBSTITUTE(C50,"_",""))))) -> #VALUE! | E50: =LEFT(C50, FIND("_", C50) - 1) -> #VALUE! | J50: FALSE | K50: FALSE | L50: FALSE
A51: =LEFT(C51, FIND("_", C51) - 1) -> #VALUE! | D51: =RIGHT(C51,LEN(C51)-FIND("@",SUBSTITUTE(C51,"_","@",LEN(C51)-LEN(SUBSTITUTE(C51,"_",""))))) -> #VALUE! | E51: =MID(C51, FIND("_", C51, FIND("_", C51) + 1) + 1, FIND("_", C51, FIND("_", C51, FIND("_", C51) + 1) + 1) - FIND("_", C51, FIND("_", C51) + 1)- 1) -> #VALUE! | J51: FALSE | K51: FALSE | L51: FALSE
A52: =LEFT(C52, FIND("_", C52) - 1) -> #VALUE! | D52: =RIGHT(C52,LEN(C52)-FIND("@",SUBSTITUTE(C52,"_","@",LEN(C52)-LEN(SUBSTITUTE(C52,"_",""))))) -> #VALUE! | E52: =MID(C52, FIND("_", C52, FIND("_", C52) + 1) + 1, FIND("_", C52, FIND("_", C52, FIND("_", C52) + 1) + 1) - FIND("_", C52, FIND("_", C52) + 1)- 1) -> #VALUE! | J52: FALSE | K52: FALSE | L52: FALSE
A53: =LEFT(C53, FIND("_", C53) - 1) -> #VALUE! | D53: =RIGHT(C53,LEN(C53)-FIND("@",SUBSTITUTE(C53,"_","@",LEN(C53)-LEN(SUBSTITUTE(C53,"_",""))))) -> #VALUE! | E53: =MID(C53, FIND("_", C53, FIND("_", C53) + 1) + 1, FIND("_", C53, FIND("_", C53, FIND("_", C53) + 1) + 1) - FIND("_", C53, FIND("_", C53) + 1)- 1) -> #VALUE! | J53: FALSE | K53: FALSE | L53: FALSE
A54: =LEFT(C54, FIND("_", C54) - 1) -> #VALUE! | D54: =RIGHT(C54,LEN(C54)-FIND("@",SUBSTITUTE(C54,"_","@",LEN(C54)-LEN(SUBSTITUTE(C54,"_",""))))) -> #VALUE! | E54: =MID(C54, FIND("_", C54, FIND("_", C54) + 1) + 1, FIND("_", C54, FIND("_", C54, FIND("_", C54) + 1) + 1) - FIND("_", C54, FIND("_", C54) + 1)- 1) -> #VALUE! | J54: FALSE | K54: FALSE | L54: FALSE
...

Sheet Dashboard
A3: Row Labels | B3: Count of Clash Status | P3: Row Labels | R3: Sum of MAJOR | S3: Sum of MINOR
A4: ACTIVE | B4: 4 | P4: 001_MAJOR_002_ST/EE_Cable tray ทะลุผ่านคาน_20230408 | R4: 0 | S4: 5
A5: RESOLVED | B5: 1 | P5: 002_MINOR_000_AR/AC_Duct ชนฝ้า_20210813
A6: Grand Total | B6: 5 | P6: 003_MAJOR_000_CI/ME_ท่อไม่ตรงกับ Manhole_20240210
P7: 004_MAJOR_000_CI/ME_ท่อไม่ตรงกับ Manhole_20240210
P8: 005_MAJOR_000_CI/ME_ท่อไม่ตรงกับ Manhole_20240210
P9: 006_MAJOR_000_CI/ME_ท่อไม่ตรงกับ Manhole_20240210
P10: (blank)
P11: Grand Total
A22: Row Labels | B22: Count of Discipline
A23: Grand Total
A49: Row Labels | B49: Count of Priority
A50: Minor | B50: 5
A51: Grand Total | B51: 5
